Workbook
Name 기인물_12대: _드롭다운참조!$J$2:$J$20
Name 기인물_일반: _드롭다운참조!$J$21:$J$58
Name 기인물_전체: _드롭다운참조!$J$2:$J$58
Name 기인물분류목록: _드롭다운참조!$AB$2:$AB$35
Name ChartItem: OFFSET(③공정조회!$X$14,0,0,MAX(1,COUNTA(③공정조회!$X$14:$X$63)),1)
Name ChartItemVal: OFFSET(③공정조회!$Y$14,0,0,MAX(1,COUNTA(③공정조회!$X$14:$X$63)),1)
Name ChartWork: OFFSET(③공정조회!$U$14,0,0,MAX(1,COUNTA(③공정조회!$U$14:$U$63)),1)
Name ChartWorkVal: OFFSET(③공정조회!$V$14,0,0,MAX(1,COUNTA(③공정조회!$U$14:$U$63)),1)
Name GJ_1: _드롭다운참조!$P$2:$P$7
Name GJ_10: _드롭다운참조!$Y$2:$Y$3
Name GJ_11: _드롭다운참조!$Z$2:$Z$6
Name GJ_12: _드롭다운참조!$AA$2:$AA$8
Name GJ_2: _드롭다운참조!$Q$2:$Q$5
Name GJ_3: _드롭다운참조!$R$2:$R$2
Name GJ_4: _드롭다운참조!$S$2:$S$9
Name GJ_5: _드롭다운참조!$T$2:$T$4
Name GJ_6: _드롭다운참조!$U$2:$U$2
Name GJ_7: _드롭다운참조!$V$2:$V$3
Name GJ_8: _드롭다운참조!$W$2:$W$5
Name GJ_9: _드롭다운참조!$X$2:$X$7
Name JK_1_1: _드롭다운참조!$A$31:$A$33
Name JK_1_2: _드롭다운참조!$B$31:$B$34
Name JK_1_3: _드롭다운참조!$C$31:$C$33
Name JK_1_4: _드롭다운참조!$D$31:$D$32
Name JK_1_5: _드롭다운참조!$E$31:$E$31
Name JK_1_6: _드롭다운참조!$F$31:$F$32
Name JK_10_1: _드롭다운참조!$AJ$31:$AJ$31
Name JK_10_2: _드롭다운참조!$AK$31:$AK$31
Name JK_11_1: _드롭다운참조!$AL$31:$AL$32
Name JK_11_2: _드롭다운참조!$AM$31:$AM$32
Name JK_11_3: _드롭다운참조!$AN$31:$AN$32
Name JK_11_4: _드롭다운참조!$AO$31:$AO$32
Name JK_11_5: _드롭다운참조!$AP$31:$AP$31
Name JK_12_1: _드롭다운참조!$AQ$31:$AQ$31
Name JK_12_2: _드롭다운참조!$AR$31:$AR$40
Name JK_12_3: _드롭다운참조!$AS$31:$AS$36
Name JK_12_4: _드롭다운참조!$AT$31:$AT$31
Name JK_12_5: _드롭다운참조!$AU$31:$AU$35
Name JK_12_6: _드롭다운참조!$AV$31:$AV$31
Name JK_12_7: _드롭다운참조!$AW$31:$AW$31
Name JK_2_1: _드롭다운참조!$G$31:$G$34
Name JK_2_2: _드롭다운참조!$H$31:$H$34
Name JK_2_3: _드롭다운참조!$I$31:$I$33
Name JK_2_4: _드롭다운참조!$J$31:$J$33
Name JK_3_1: _드롭다운참조!$K$31:$K$33
Name JK_4_1: _드롭다운참조!$L$31:$L$33
Name JK_4_2: _드롭다운참조!$M$31:$M$31
Name JK_4_3: _드롭다운참조!$N$31:$N$33
Name JK_4_4: _드롭다운참조!$O$31:$O$33
Name JK_4_5: _드롭다운참조!$P$31:$P$32
Name JK_4_6: _드롭다운참조!$Q$31:$Q$32
Name JK_4_7: _드롭다운참조!$R$31:$R$32
Name JK_4_8: _드롭다운참조!$S$31:$S$32
Name JK_5_1: _드롭다운참조!$T$31:$T$34
Name JK_5_2: _드롭다운참조!$U$31:$U$32
Name JK_5_3: _드롭다운참조!$V$31:$V$32
Name JK_6_1: _드롭다운참조!$W$31:$W$32
Name JK_7_1: _드롭다운참조!$X$31:$X$32
Name JK_7_2: _드롭다운참조!$Y$31:$Y$31
Name JK_8_1: _드롭다운참조!$Z$31:$Z$32

Sheet ③공정조회
A1: 📋 공정별 재해사례 조회 — KOEN · 공종 · 작업명 · 단위작업 · 기인물 순차 필터
B3: ① KOEN 공정 | D3: YES | F3: ※ ①→②→③→④→⑤ 순서로 선택하세요. 상위 항목 변경 시 하위를 다시 선택하세요.
B4: ② 공종 | D4: 11. 기타 토목공사 | F4: {=IF($D$4="","← 비워두면 전체 공종 조회",SUMPRODUCT(((($D$3<>"YES")+($D$3="YES")*(DB!E$2:E$2576="YES"))*(DB!B$2:B$2576=$D$4))*1)&"건")} -> 156건 | G4: {=IF(AND($D$4<>"",SUMPRODUCT(((($D$3<>"YES")+($D$3="YES")*(DB!E$2:E$2576="YES"))*(DB!B$2:B$2576=$D$4))*1)=0),"⚠ 해당없음!","")}
B5: ③ 작업명 | F5: {=IF($D$5="","← 비워두면 전체 작업명 조회",SUMPRODUCT(((($D$3<>"YES")+($D$3="YES")*(DB!E$2:E$2576="YES"))*(($D$4="")+($D$4<>"")*(DB!B$2:B$2576=$D$4))*(DB!C$2:C$2576=$D$5))*1)&"건")} -> ← 비워두면 전체 작업명 조회 | G5: {=IF(AND($D$5<>"",SUMPRODUCT(((($D$3<>"YES")+($D$3="YES")*(DB!E$2:E$2576="YES"))*(($D$4="")+($D$4<>"")*(DB!B$2:B$2576=$D$4))*(DB!C$2:C$2576=$D$5))*1)=0),"⚠ 상위변경! 다시선택","")} | H5: =IF($D$5="","← 작업명 선택 시 관련 기인물 표시",IFERROR(_xlfn.LET(_xlpm._txt,_xlfn.TEXTJOIN(" / ",TRUE,INDEX(_드롭다운참조!IB$2:JX$41,,MATCH($D$5,_드롭다운참조!$IB$1:$JX$1,0))),_xlpm._cnt,(LEN(_xlpm._txt)-LEN(SUBSTITUTE(_xlpm._txt," / ","")))/3+1,"✓관련 기인물 (총 "&_xlpm._cnt&"종) : "&_xlpm._txt),"해당 없음")) -> ← 작업명 선택 시 관련 기인물 표시
B6: ④ 단위작업명 | F6: {=IF($D$6="","← 비워두면 전체 단위작업 조회",SUMPRODUCT(((($D$3<>"YES")+($D$3="YES")*(DB!E$2:E$2576="YES"))*(($D$4="")+($D$4<>"")*(DB!B$2:B$2576=$D$4))*(($D$5="")+($D$5<>"")*(DB!C$2:C$2576=$D$5))*(DB!D$2:D$2576=$D$6))*1)&"건")} -> ← 비워두면 전체 단위작업 조회 | G6: {=IF(AND($D$6<>"",SUMPRODUCT(((($D$3<>"YES")+($D$3="YES")*(DB!E$2:E$2576="YES"))*(($D$4="")+($D$4<>"")*(DB!B$2:B$2576=$D$4))*(($D$5="")+($D$5<>"")*(DB!C$2:C$2576=$D$5))*(DB!D$2:D$2576=$D$6))*1)=0),"⚠ 상위변경! 다시선택","")} | H6: =IF($D$6="","← 단위작업명 선택 시 관련 기인물 표시",IFERROR(_xlfn.LET(_xlpm._txt,_xlfn.TEXTJOIN(" / ",TRUE,INDEX(_드롭다운참조!DS$2:IA$41,,MATCH($D$6,_드롭다운참조!$DS$1:$IA$1,0))),_xlpm._cnt,(LEN(_xlpm._txt)-LEN(SUBSTITUTE(_xlpm._txt," / ","")))/3+1,"✓관련 기인물 (총 "&_xlpm._cnt&"종): "&_xlpm._txt),"해당 없음")) -> ← 단위작업명 선택 시 관련 기인물 표시
B7: ⑤ 기인물 | F7: 전체 | H7: =IF($F$7="전체","← 전체 구분 조회",IF($F$7="12대 기인물","✅ 12대 기인물만 필터","✅ 해당없음만 필터")) -> ← 전체 구분 조회
B9: 조회 결과 | D9: {=SUMPRODUCT(((($D$3<>"YES")+($D$3="YES")*(DB!E$2:E$2576="YES"))*1)*(($D$4="")+($D$4<>"")*(DB!B$2:B$2576=$D$4))*(($D$5="")+($D$5<>"")*(DB!C$2:C$2576=$D$5))*(($D$6="")+($D$6<>"")*(DB!D$2:D$2576=$D$6))*(($D$7="")+($D$7<>"")*(ISNUMBER(SEARCH($D$7,DB!G$2:G$2576))))*(($F$7="전체")+($F$7<>"전체")*(DB!H$2:H$2576=$F$7)))} -> 156 | F9: ="건 (DB 총 "&COUNTA(DB!A2:A2576)&"건 중)" -> 건 (DB 총 2574건 중) | L9: 적용 필터 경로: | N9: =IF(D3="YES","발전소(KOEN=YES)",IF(D3="전체","전체",""))&IF(D4<>""," ▶ "&D4,"")&IF(D5<>""," ▶ "&D5,"")&IF(D6<>""," ▶ "&D6,"")&IF(D7<>""," ▶ "&D7,"") -> 발전소(KOEN=YES) ▶ 11. 기타 토목공사
B11: No | D11: 기인물 | F11: 재해형태 | H11: 재해개요 | J11: 재해유발요인 | L11: 위험성 감소대책 | U11: 🔨 작업명 (건수순) | V11: ▶ 건수 | X11: 🔧 기인물 (건수순) | Y11: ▶ 건수
U13: 작업명 | V13: 건수 | X13: 기인물 | Y13: 건수
B14: =IFERROR(IF(T14="","",ROW()-13),"") -> 1 | D14: {=IFERROR(INDEX(DB!G$2:G$2576,T14),"")} -> 각재(파이프,강관,합판) | F14: {=IFERROR(INDEX(DB!O$2:O$2576,T14),"")} -> 깔림 뒤집힘 | H14: {=IFERROR(INDEX(DB!P$2:P$2576,T14),"")} -> 2020년 6월경 OOO도 OO군 OOO면 소재 (주)OOOO 자재 야적장에서 재해자가 화물차량(25.5톤) 높이 약 1.7 m 적재함 위에서 크레인(10톤)으로 인양된 강관파이프(하수관거*)를 차량에 적재하던 중, 3단으로 불안정하게 적재된 강관파이프가 붕괴되어 재해자가 야적장 바닥으로 떨어졌으며, 이때 차량 적재함에서 낙하한 강관파이프(약 390kg)에 깔려서 사망한 재해임._x000D_ | J14: {=IFERROR(INDEX(DB!Q$2:Q$2576,T14),"")} -> 크레인으로 인양된 강관파이프를 차량에 적재하던 중, 3단으로 불안정하게 적재된 강관파이프가 붕괴되어 강관파이프에 깔림 | L14: {=IFERROR(INDEX(DB!R$2:R$2576,T14),"")} -> ▶ 자재를 야적하는 경우 평탄한 곳에 적재하며 구름방지조치 실시 ▶ 경사면에서 흄관을 고정하기 위해 쐐기 등을 이용 ▶ 강관파이프를 3단이상 등 과도하게 적재 금지 | P14: {=IFERROR(_xlfn.AGGREGATE(15,6,ROW(DB!A$2:A$2576)/((($D$3<>"YES")+($D$3="YES")*(DB!E$2:E$2576="YES"))*(($D$4="")+($D$4<>"")*( DB!B$2:B$2576=$D$4))*(($D$5="")+($D$5<>"")*( DB!C$2:C$2576=$D$5))*(($D$6="")+($D$6<>"")*( DB!D$2:D$2576=$D$6))*(($D$7="")+($D$7<>"")*(ISNUMBER(SEARCH($D$7,DB!G$2:G$2576))))*(($F$7="전체")+($F$7<>"전체")*(DB!H$2:H$2576=$F$7))),ROW()-13)-1,"")} -> 1 | Q14: {=IFERROR(INDEX(DB!G$2:G$2576,P14),"")} -> 각재(파이프,강관,합판) | R14: {=IFERROR(INDEX(DB!O$2:O$2576,P14),"")} -> 맞음 | S14: =IF(P14="","",COUNTIF($Q$14:$Q$2587,"<"&Q14)*100+COUNTIF($R$14:$R$2587,"<"&R14)+(ROW()-13)*0.001) -> 244275 | T14: =IFERROR(INDEX($P$14:$P$2587,MATCH(SMALL($S$14:$S$2587,ROW()-13),$S$14:$S$2587,0)),"") -> 2 | U14: {=IFERROR(INDEX(AA$14:AA$63,_xlfn.AGGREGATE(15,6,ROW(AA$14:AA$63)-ROW(AA$14)+1/(AB$14:AB$63=LARGE(AB$14:AB$63,1)),1)),"")} -> 11.4 맨홀 및 관부설작업 | V14: =IF(U14="","",IFERROR(LARGE(AB$14:AB$63,ROW()-13),"")) -> 106 | X14: {=IFERROR(INDEX(AD$14:AD$63,_xlfn.AGGREGATE(15,6,ROW(AD$14:AD$63)-ROW(AD$14)+1/(AE$14:AE$63=LARGE(AE$14:AE$63,1)),1)),"")} -> 토사 | Y14: =IF(X14="","",IFERROR(LARGE(AE$14:AE$63,ROW()-13),"")) -> 47 | AA14: {=IFERROR(INDEX(DB!$C$2:$C$2576,_xlfn.AGGREGATE(15,6,ROW(DB!$C$2:$C$2576)-1/((($D$3<>"YES")+($D$3="YES")*(DB!$E$2:$E$2576="YES"))*(($D$4="")+($D$4<>"")*(DB!$B$2:$B$2576=$D$4))*(($F$7="전체")+($F$7<>"전체")*(DB!$H$2:$H$2576=$F$7))*(COUNTIF(AA$13:AA13,DB!$C$2:$C$2576)=0)),1)),"")} -> 11.1 부대 토목 작업 | AB14: {=IF(AA14="","",SUMPRODUCT(((($D$3<>"YES")+($D$3="YES")*(DB!$E$2:$E$2576="YES"))*(($D$4="")+($D$4<>"")*(DB!$B$2:$B$2576=$D$4))*(($F$7="전체")+($F$7<>"전체")*(DB!$H$2:$H$2576=$F$7)))*(DB!$C$2:$C$2576=AA14)*1))} -> 36 | AD14: {=IFERROR(INDEX(DB!$G$2:$G$2576,_xlfn.AGGREGATE(15,6,ROW(DB!$G$2:$G$2576)-1/((($D$3<>"YES")+($D$3="YES")*(DB!$E$2:$E$2576="YES"))*(($D$4="")+($D$4<>"")*(DB!$B$2:$B$2576=$D$4))*(($D$5="")+($D$5<>"")*(DB!$C$2:$C$2576=$D$5))*(($D$6="")+($D$6<>"")*(DB!$D$2:$D$2576=$D$6))*(($D$7="")+($D$7<>"")*(ISNUMBER(SEARCH($D$7,DB!$G$2:$G$2576))))*(($F$7="전체")+($F$7<>"전체")*(DB!$H$2:$H$2576=$F$7))*(COUNTIF(AD$13:AD13,DB!$G$2:$G$2576)=0)),1)),"")} -> 각재(파이프,강관,합판) | AE14: {=IF(AD14="","",SUMPRODUCT(((($D$3<>"YES")+($D$3="YES")*(DB!$E$2:$E$2576="YES"))*(($D$4="")+($D$4<>"")*(DB!$B$2:$B$2576=$D$4))*(($D$5="")+($D$5<>"")*(DB!$C$2:$C$2576=$D$5))*(($D$6="")+($D$6<>"")*(DB!$D$2:$D$2576=$D$6))*(($D$7="")+($D$7<>"")*(ISNUMBER(SEARCH($D$7,DB!$G$2:$G$2576))))*(($F$7="전체")+($F$7<>"전체")*(DB!$H$2:$H$2576=$F$7)))*(DB!$G$2:$G$2576=AD14)*1))} -> 3
B15: =IFERROR(IF(T15="","",ROW()-13),"") -> 2 | D15: {=IFERROR(INDEX(DB!G$2:G$2576,T15),"")} -> 각재(파이프,강관,합판) | F15: {=IFERROR(INDEX(DB!O$2:O$2576,T15),"")} -> 맞음 | H15: {=IFERROR(INDEX(DB!P$2:P$2576,T15),"")} -> 2015년 12월경 군부대 방호문 설치공사에서 재해자가 보강초 벽체에 각재를 대어 기울어진 보강토 블록 벽체를 바로 세우는 작업 중 굴착기 버킷으로 힘을 가하다 각재가 갑자기 이탈되면서 힘을 가하던 굴착기 버킷에 맞아 사망 | J15: {=IFERROR(INDEX(DB!Q$2:Q$2576,T15),"")} -> 보강토 벽체에 각재를 대어 굴삭기 버켓으로 힘을 가하던 과정에서 각재가 갑자기 이탈되면서 타격함 | L15: {=IFERROR(INDEX(DB!R$2:R$2576,T15),"")} -> ▶ 굴삭기 작업시 토사의 굴착, 절토 등 장비용도에 맞게 사용 ▶ 건설기계 제원, 성능, 작업반경 등을 고려하여 작업 | P15: {=IFERROR(_xlfn.AGGREGATE(15,6,ROW(DB!A$2:A$2576)/((($D$3<>"YES")+($D$3="YES")*(DB!E$2:E$2576="YES"))*(($D$4="")+($D$4<>"")*( DB!B$2:B$2576=$D$4))*(($D$5="")+($D$5<>"")*( DB!C$2:C$2576=$D$5))*(($D$6="")+($D$6<>"")*( DB!D$2:D$2576=$D$6))*(($D$7="")+($D$7<>"")*(ISNUMBER(SEARCH($D$7,DB!G$2:G$2576))))*(($F$7="전체")+($F$7<>"전체")*(DB!H$2:H$2576=$F$7))),ROW()-13)-1,"")} -> 2 | Q15: {=IFERROR(INDEX(DB!G$2:G$2576,P15),"")} -> 각재(파이프,강관,합판) | R15: {=IFERROR(INDEX(DB!O$2:O$2576,P15),"")} -> 깔림 뒤집힘 | S15: =IF(P15="","",COUNTIF($Q$14:$Q$2587,"<"&Q15)*100+COUNTIF($R$14:$R$2587,"<"&R15)+(ROW()-13)*0.001) -> 244220 | T15: =IFERROR(INDEX($P$14:$P$2587,MATCH(SMALL($S$14:$S$2587,ROW()-13),$S$14:$S$2587,0)),"") -> 1 | U15: {=IFERROR(INDEX(AA$14:AA$63,_xlfn.AGGREGATE(15,6,ROW(AA$14:AA$63)-ROW(AA$14)+1/(AB$14:AB$63=LARGE(AB$14:AB$63,ROW()-13)),COUNTIF(V$14:V14,LARGE(AB$14:AB$63,ROW()-13))+1)),"")} -> 11.1 부대 토목 작업 | V15: =IF(U15="","",IFERROR(LARGE(AB$14:AB$63,ROW()-13),"")) -> 36 | X15: {=IFERROR(INDEX(AD$14:AD$63,_xlfn.AGGREGATE(15,6,ROW(AD$14:AD$63)-ROW(AD$14)+1/(AE$14:AE$63=LARGE(AE$14:AE$63,ROW()-13)),COUNTIF(Y$14:Y14,LARGE(AE$14:AE$63,ROW()-13))+1)),"")} -> 굴착기 | Y15: =IF(X15="","",IFERROR(LARGE(AE$14:AE$63,ROW()-13),"")) -> 31 | AA15: {=IFERROR(INDEX(DB!$C$2:$C$2576,_xlfn.AGGREGATE(15,6,ROW(DB!$C$2:$C$2576)-1/((($D$3<>"YES")+($D$3="YES")*(DB!$E$2:$E$2576="YES"))*(($D$4="")+($D$4<>"")*(DB!$B$2:$B$2576=$D$4))*(($F$7="전체")+($F$7<>"전체")*(DB!$H$2:$H$2576=$F$7))*(COUNTIF(AA$13:AA14,DB!$C$2:$C$2576)=0)),1)),"")} -> 11.4 맨홀 및 관부설작업 | AB15: {=IF(AA15="","",SUMPRODUCT(((($D$3<>"YES")+($D$3="YES")*(DB!$E$2:$E$2576="YES"))*(($D$4="")+($D$4<>"")*(DB!$B$2:$B$2576=$D$4))*(($F$7="전체")+($F$7<>"전체")*(DB!$H$2:$H$2576=$F$7)))*(DB!$C$2:$C$2576=AA15)*1))} -> 106 | AD15: {=IFERROR(INDEX(DB!$G$2:$G$2576,_xlfn.AGGREGATE(15,6,ROW(DB!$G$2:$G$2576)-1/((($D$3<>"YES")+($D$3="YES")*(DB!$E$2:$E$2576="YES"))*(($D$4="")+($D$4<>"")*(DB!$B$2:$B$2576=$D$4))*(($D$5="")+($D$5<>"")*(DB!$C$2:$C$2576=$D$5))*(($D$6="")+($D$6<>"")*(DB!$D$2:$D$2576=$D$6))*(($D$7="")+($D$7<>"")*(ISNUMBER(SEARCH($D$7,DB!$G$2:$G$2576))))*(($F$7="전체")+($F$7<>"전체")*(DB!$H$2:$H$2576=$F$7))*(COUNTIF(AD$13:AD14,DB!$G$2:$G$2576)=0)),1)),"")} -> 굴착기 | AE15: {=IF(AD15="","",SUMPRODUCT(((($D$3<>"YES")+($D$3="YES")*(DB!$E$2:$E$2576="YES"))*(($D$4="")+($D$4<>"")*(DB!$B$2:$B$2576=$D$4))*(($D$5="")+($D$5<>"")*(DB!$C$2:$C$2576=$D$5))*(($D$6="")+($D$6<>"")*(DB!$D$2:$D$2576=$D$6))*(($D$7="")+($D$7<>"")*(ISNUMBER(SEARCH($D$7,DB!$G$2:$G$2576))))*(($F$7="전체")+($F$7<>"전체")*(DB!$H$2:$H$2576=$F$7)))*(DB!$G$2:$G$2576=AD15)*1))} -> 31
B16: =IFERROR(IF(T16="","",ROW()-13),"") -> 3 | D16: {=IFERROR(INDEX(DB!G$2:G$2576,T16),"")} -> 각재(파이프,강관,합판) | F16: {=IFERROR(INDEX(DB!O$2:O$2576,T16),"")} -> 맞음 | H16: {=IFERROR(INDEX(DB!P$2:P$2576,T16),"")} -> 2021년 4월경 OOO도 OO시 OO동 소재 OOOO(주) OOOO 노후 상수관망 정비 공사 현장에서 화물차에 적재되어 있는 주철관을 슬링벨트로 묶어 하역하는 준비 작업 중 주철관이 슬링벨트 밖으로 이탈하며 재해자를 덮쳐 약 1.85m 높이의 차량 측면에서 바닥으로 떨어져 사망한 재해임 | J16: {=IFERROR(INDEX(DB!Q$2:Q$2576,T16),"")} -> 관로 정비 공사 현장에서 화물차에 적재되어 있는 주철관을 슬링벨트로 묶어 하역하는 준비 작업 중 주철관이 슬링벨트 밖으로 이탈하며 재해자를 덮침 | L16: {=IFERROR(INDEX(DB!R$2:R$2576,T16),"")} -> ▶ 화물적재 작업 시 최대 적재량 및 한쪽으로 치우치지 않은 적재 등의 조치 준수 ▶ 로프 풀기 작업 전 적재함 주변에 근로자의 통행을 통제한 뒤 하역작업 실시 | P16: {=IFERROR(_xlfn.AGGREGATE(15,6,ROW(DB!A$2:A$2576)/((($D$3<>"YES")+($D$3="YES")*(DB!E$2:E$2576="YES"))*(($D$4="")+($D$4<>"")*( DB!B$2:B$2576=$D$4))*(($D$5="")+($D$5<>"")*( DB!C$2:C$2576=$D$5))*(($D$6="")+($D$6<>"")*( DB!D$2:D$2576=$D$6))*(($D$7="")+($D$7<>"")*(ISNUMBER(SEARCH($D$7,DB!G$2:G$2576))))*(($F$7="전체")+($F$7<>"전체")*(DB!H$2:H$2576=$F$7))),ROW()-13)-1,"")} -> 3 | Q16: {=IFERROR(INDEX(DB!G$2:G$2576,P16),"")} -> 각재(파이프,강관,합판) | R16: {=IFERROR(INDEX(DB!O$2:O$2576,P16),"")} -> 맞음 | S16: =IF(P16="","",COUNTIF($Q$14:$Q$2587,"<"&Q16)*100+COUNTIF($R$14:$R$2587,"<"&R16)+(ROW()-13)*0.001) -> 244275 | T16: =IFERROR(INDEX($P$14:$P$2587,MATCH(SMALL($S$14:$S$2587,ROW()-13),$S$14:$S$2587,0)),"") -> 3 | U16: {=IFERROR(INDEX(AA$14:AA$63,_xlfn.AGGREGATE(15,6,ROW(AA$14:AA$63)-ROW(AA$14)+1/(AB$14:AB$63=LARGE(AB$14:AB$63,ROW()-13)),COUNTIF(V$14:V15,LARGE(AB$14:AB$63,ROW()-13))+1)),"")} -> 11.2 가설도로 작업 | V16: =IF(U16="","",IFERROR(LARGE(AB$14:AB$63,ROW()-13),"")) -> 7 | X16: {=IFERROR(INDEX(AD$14:AD$63,_xlfn.AGGREGATE(15,6,ROW(AD$14:AD$63)-ROW(AD$14)+1/(AE$14:AE$63=LARGE(AE$14:AE$63,ROW()-13)),COUNTIF(Y$14:Y15,LARGE(AE$14:AE$63,ROW()-13))+1)),"")} -> 트럭 | Y16: =IF(X16="","",IFERROR(LARGE(AE$14:AE$63,ROW()-13),"")) -> 11 | AA16: {=IFERROR(INDEX(DB!$C$2:$C$2576,_xlfn.AGGREGATE(15,6,ROW(DB!$C$2:$C$2576)-1/((($D$3<>"YES")+($D$3="YES")*(DB!$E$2:$E$2576="YES"))*(($D$4="")+($D$4<>"")*(DB!$B$2:$B$2576=$D$4))*(($F$7="전체")+($F$7<>"전체")*(DB!$H$2:$H$2576=$F$7))*(COUNTIF(AA$13:AA15,DB!$C$2:$C$2576)=0)),1)),"")} -> 11.2 가설도로 작업 | AB16: {=IF(AA16="","",SUMPRODUCT(((($D$3<>"YES")+($D$3="YES")*(DB!$E$2:$E$2576="YES"))*(($D$4="")+($D$4<>"")*(DB!$B$2:$B$2576=$D$4))*(($F$7="전체")+($F$7<>"전체")*(DB!$H$2:$H$2576=$F$7)))*(DB!$C$2:$C$2576=AA16)*1))} -> 7 | AD16: {=IFERROR(INDEX(DB!$G$2:$G$2576,_xlfn.AGGREGATE(15,6,ROW(DB!$G$2:$G$2576)-1/((($D$3<>"YES")+($D$3="YES")*(DB!$E$2:$E$2576="YES"))*(($D$4="")+($D$4<>"")*(DB!$B$2:$B$2576=$D$4))*(($D$5="")+($D$5<>"")*(DB!$C$2:$C$2576=$D$5))*(($D$6="")+($D$6<>"")*(DB!$D$2:$D$2576=$D$6))*(($D$7="")+($D$7<>"")*(ISNUMBER(SEARCH($D$7,DB!$G$2:$G$2576))))*(($F$7="전체")+($F$7<>"전체")*(DB!$H$2:$H$2576=$F$7))*(COUNTIF(AD$13:AD15,DB!$G$2:$G$2576)=0)),1)),"")} -> 콘크리트펌프카 | AE16: {=IF(AD16="","",SUMPRODUCT(((($D$3<>"YES")+($D$3="YES")*(DB!$E$2:$E$2576="YES"))*(($D$4="")+($D$4<>"")*(DB!$B$2:$B$2576=$D$4))*(($D$5="")+($D$5<>"")*(DB!$C$2:$C$2576=$D$5))*(($D$6="")+($D$6<>"")*(DB!$D$2:$D$2576=$D$6))*(($D$7="")+($D$7<>"")*(ISNUMBER(SEARCH($D$7,DB!$G$2:$G$2576))))*(($F$7="전체")+($F$7<>"전체")*(DB!$H$2:$H$2576=$F$7)))*(DB!$G$2:$G$2576=AD16)*1))} -> 1
B17: =IFERROR(IF(T17="","",ROW()-13),"") -> 4 | D17: {=IFERROR(INDEX(DB!G$2:G$2576,T17),"")} -> 굴착기 | F17: {=IFERROR(INDEX(DB!O$2:O$2576,T17),"")} -> 깔림 뒤집힘 | H17: {=IFERROR(INDEX(DB!P$2:P$2576,T17),"")} -> 2016년 12월경 초등학교 신축공사 현장에서 재해자(장비운전원)가 경계석 설치작업 중 굴착기 버킷에 골재를 담아 이동 후 회전하다 무게중심을 잃고 전도되면서 장비에 깔려 사망 | J17: {=IFERROR(INDEX(DB!Q$2:Q$2576,T17),"")} -> 굴삭기가 이동 중 붐을 펼치고 회전하는 순간 무게중심을 잃고 전도되어 근로자가 장비에 깔림 | L17: {=IFERROR(INDEX(DB!R$2:R$2576,T17),"")} -> ▶ 중량물을 인양한 상태에서 무리한 속도로 회전하는 등의 장비조작 금지 ▶ 전도를 예방하기 위해 굴삭기 이동경로 및 작업 장소 등의 지반을 평탄화 작업 실시 ▶ 중량물 인양 시 굴삭기의 정격하중을 준수하여 무리한 중량물 인양 금지 | P17: {=IFERROR(_xlfn.AGGREGATE(15,6,ROW(DB!A$2:A$2576)/((($D$3<>"YES")+($D$3="YES")*(DB!E$2:E$2576="YES"))*(($D$4="")+($D$4<>"")*( DB!B$2:B$2576=$D$4))*(($D$5="")+($D$5<>"")*( DB!C$2:C$2576=$D$5))*(($D$6="")+($D$6<>"")*( DB!D$2:D$2576=$D$6))*(($D$7="")+($D$7<>"")*(ISNUMBER(SEARCH($D$7,DB!G$2:G$2576))))*(($F$7="전체")+($F$7<>"전체")*(DB!H$2:H$2576=$F$7))),ROW()-13)-1,"")} -> 361 | Q17: {=IFERROR(INDEX(DB!G$2:G$2576,P17),"")} -> 굴착기 | R17: {=IFERROR(INDEX(DB!O$2:O$2576,P17),"")} -> 부딪힘 접촉 | S17: =IF(P17="","",COUNTIF($Q$14:$Q$2587,"<"&Q17)*100+COUNTIF($R$14:$R$2587,"<"&R17)+(ROW()-13)*0.001) -> 244741 | T17: =IFERROR(INDEX($P$14:$P$2587,MATCH(SMALL($S$14:$S$2587,ROW()-13),$S$14:$S$2587,0)),"") -> 371 | U17: {=IFERROR(INDEX(AA$14:AA$63,_xlfn.AGGREGATE(15,6,ROW(AA$14:AA$63)-ROW(AA$14)+1/(AB$14:AB$63=LARGE(AB$14:AB$63,ROW()-13)),COUNTIF(V$14:V16,LARGE(AB$14:AB$63,ROW()-13))+1)),"")} -> 11.3 지장물 조사 및 이설 작업 | V17: =IF(U17="","",IFERROR(LARGE(AB$14:AB$63,ROW()-13),"")) -> 7 | X17: {=IFERROR(INDEX(AD$14:AD$63,_xlfn.AGGREGATE(15,6,ROW(AD$14:AD$63)-ROW(AD$14)+1/(AE$14:AE$63=LARGE(AE$14:AE$63,ROW()-13)),COUNTIF(Y$14:Y16,LARGE(AE$14:AE$63,ROW()-13))+1)),"")} -> 기타구조물 | Y17: =IF(X17="","",IFERROR(LARGE(AE$14:AE$63,ROW()-13),"")) -> 7 | AA17: {=IFERROR(INDEX(DB!$C$2:$C$2576,_xlfn.AGGREGATE(15,6,ROW(DB!$C$2:$C$2576)-1/((($D$3<>"YES")+($D$3="YES")*(DB!$E$2:$E$2576="YES"))*(($D$4="")+($D$4<>"")*(DB!$B$2:$B$2576=$D$4))*(($F$7="전체")+($F$7<>"전체")*(DB!$H$2:$H$2576=$F$7))*(COUNTIF(AA$13:AA16,DB!$C$2:$C$2576)=0)),1)),"")} -> 11.3 지장물 조사 및 이설 작업 | AB17: {=IF(AA17="","",SUMPRODUCT(((($D$3<>"YES")+($D$3="YES")*(DB!$E$2:$E$2576="YES"))*(($D$4="")+($D$4<>"")*(DB!$B$2:$B$2576=$D$4))*(($F$7="전체")+($F$7<>"전체")*(DB!$H$2:$H$2576=$F$7)))*(DB!$C$2:$C$2576=AA17)*1))} -> 7 | AD17: {=IFERROR(INDEX(DB!$G$2:$G$2576,_xlfn.AGGREGATE(15,6,ROW(DB!$G$2:$G$2576)-1/((($D$3<>"YES")+($D$3="YES")*(DB!$E$2:$E$2576="YES"))*(($D$4="")+($D$4<>"")*(DB!$B$2:$B$2576=$D$4))*(($D$5="")+($D$5<>"")*(DB!$C$2:$C$2576=$D$5))*(($D$6="")+($D$6<>"")*(DB!$D$2:$D$2576=$D$6))*(($D$7="")+($D$7<>"")*(ISNUMBER(SEARCH($D$7,DB!$G$2:$G$2576))))*(($F$7="전체")+($F$7<>"전체")*(DB!$H$2:$H$2576=$F$7))*(COUNTIF(AD$13:AD16,DB!$G$2:$G$2576)=0)),1)),"")} -> 이동식크레인 | AE17: {=IF(AD17="","",SUMPRODUCT(((($D$3<>"YES")+($D$3="YES")*(DB!$E$2:$E$2576="YES"))*(($D$4="")+($D$4<>"")*(DB!$B$2:$B$2576=$D$4))*(($D$5="")+($D$5<>"")*(DB!$C$2:$C$2576=$D$5))*(($D$6="")+($D$6<>"")*(DB!$D$2:$D$2576=$D$6))*(($D$7="")+($D$7<>"")*(ISNUMBER(SEARCH($D$7,DB!$G$2:$G$2576))))*(($F$7="전체")+($F$7<>"전체")*(DB!$H$2:$H$2576=$F$7)))*(DB!$G$2:$G$2576=AD17)*1))} -> 1
B18: =IFERROR(IF(T18="","",ROW()-13),"") -> 5 | D18: {=IFERROR(INDEX(DB!G$2:G$2576,T18),"")} -> 굴착기 | F18: {=IFERROR(INDEX(DB!O$2:O$2576,T18),"")} -> 깔림 뒤집힘 | H18: {=IFERROR(INDEX(DB!P$2:P$2576,T18),"")} -> 2021년 3월경 배수관로 설치공사에서 재해자가 빗자루를 이용하여 아스팔트 파편 정리작업을 하던 중 버킷을 교체하고 후진하던 굴착기 바퀴에 깔려 사망 | J18: {=IFERROR(INDEX(DB!Q$2:Q$2576,T18),"")} -> 아스팔트 파편 정리작업 중 후진하는 굴삭기 바퀴에 깔림 | L18: {=IFERROR(INDEX(DB!R$2:R$2576,T18),"")} -> ▶ 근로자가 건설기계에 근접하여 작업을 수행하는 경우 유도자를 배치하여 안전한 상태에서 작업 진행 ▶ 차량계 건설기계 접촉 가능 장소 및 사각지대 발생가능성이 높은 건설기계 사용 시 근로자 출입금지 및 유도자 배치 ▶ 건설장비 작업 시 근로자와 장비의 동선을 분리 ▶ 카메라 부착 또는 후방에 근로자의 접근을 알리는 후방센서, 경보장치 등 부착 ▶ 차량계 건설기계 작업전 안전 점검 실시 및 후방카메라 등 방호장치 확인 | P18: {=IFERROR(_xlfn.AGGREGATE(15,6,ROW(DB!A$2:A$2576)/((($D$3<>"YES")+($D$3="YES")*(DB!E$2:E$2576="YES"))*(($D$4="")+($D$4<>"")*( DB!B$2:B$2576=$D$4))*(($D$5="")+($D$5<>"")*( DB!C$2:C$2576=$D$5))*(($D$6="")+($D$6<>"")*( DB!D$2:D$2576=$D$6))*(($D$7="")+($D$7<>"")*(ISNUMBER(SEARCH($D$7,DB!G$2:G$2576))))*(($F$7="전체")+($F$7<>"전체")*(DB!H$2:H$2576=$F$7))),ROW()-13)-1,"")} -> 362 | Q18: {=IFERROR(INDEX(DB!G$2:G$2576,P18),"")} -> 콘크리트펌프카 | R18: {=IFERROR(INDEX(DB!O$2:O$2576,P18),"")} -> 맞음 | S18: =IF(P18="","",COUNTIF($Q$14:$Q$2587,"<"&Q18)*100+COUNTIF($R$14:$R$2587,"<"&R18)+(ROW()-13)*0.001) -> 253275.01 | T18: =IFERROR(INDEX($P$14:$P$2587,MATCH(SMALL($S$14:$S$2587,ROW()-13),$S$14:$S$2587,0)),"") -> 374 | U18: {=IFERROR(INDEX(AA$14:AA$63,_xlfn.AGGREGATE(15,6,ROW(AA$14:AA$63)-ROW(AA$14)+1/(AB$14:AB$63=LARGE(AB$14:AB$63,ROW()-13)),COUNTIF(V$14:V17,LARGE(AB$14:AB$63,ROW()-13))+1)),"")} | V18: =IF(U18="","",IFERROR(LARGE(AB$14:AB$63,ROW()-13),"")) | X18: {=IFERROR(INDEX(AD$14:AD$63,_xlfn.AGGREGATE(15,6,ROW(AD$14:AD$63)-ROW(AD$14)+1/(AE$14:AE$63=LARGE(AE$14:AE$63,ROW()-13)),COUNTIF(Y$14:Y17,LARGE(AE$14:AE$63,ROW()-13))+1)),"")} -> 물 | Y18: =IF(X18="","",IFERROR(LARGE(AE$14:AE$63,ROW()-13),"")) -> 6 | AA18: {=IFERROR(INDEX(DB!$C$2:$C$2576,_xlfn.AGGREGATE(15,6,ROW(DB!$C$2:$C$2576)-1/((($D$3<>"YES")+($D$3="YES")*(DB!$E$2:$E$2576="YES"))*(($D$4="")+($D$4<>"")*(DB!$B$2:$B$2576=$D$4))*(($F$7="전체")+($F$7<>"전체")*(DB!$H$2:$H$2576=$F$7))*(COUNTIF(AA$13:AA17,DB!$C$2:$C$2576)=0)),1)),"")} | AB18: {=IF(AA18="","",SUMPRODUCT(((($D$3<>"YES")+($D$3="YES")*(DB!$E$2:$E$2576="YES"))*(($D$4="")+($D$4<>"")*(DB!$B$2:$B$2576=$D$4))*(($F$7="전체")+($F$7<>"전체")*(DB!$H$2:$H$2576=$F$7)))*(DB!$C$2:$C$2576=AA18)*1))} | AD18: {=IFERROR(INDEX(DB!$G$2:$G$2576,_xlfn.AGGREGATE(15,6,ROW(DB!$G$2:$G$2576)-1/((($D$3<>"YES")+($D$3="YES")*(DB!$E$2:$E$2576="YES"))*(($D$4="")+($D$4<>"")*(DB!$B$2:$B$2576=$D$4))*(($D$5="")+($D$5<>"")*(DB!$C$2:$C$2576=$D$5))*(($D$6="")+($D$6<>"")*(DB!$D$2:$D$2576=$D$6))*(($D$7="")+($D$7<>"")*(ISNUMBER(SEARCH($D$7,DB!$G$2:$G$2576))))*(($F$7="전체")+($F$7<>"전체")*(DB!$H$2:$H$2576=$F$7))*(COUNTIF(AD$13:AD17,DB!$G$2:$G$2576)=0)),1)),"")} -> 로울러 | AE18: {=IF(AD18="","",SUMPRODUCT(((($D$3<>"YES")+($D$3="YES")*(DB!$E$2:$E$2576="YES"))*(($D$4="")+($D$4<>"")*(DB!$B$2:$B$2576=$D$4))*(($D$5="")+($D$5<>"")*(DB!$C$2:$C$2576=$D$5))*(($D$6="")+($D$6<>"")*(DB!$D$2:$D$2576=$D$6))*(($D$7="")+($D$7<>"")*(ISNUMBER(SEARCH($D$7,DB!$G$2:$G$2576))))*(($F$7="전체")+($F$7<>"전체")*(DB!$H$2:$H$2576=$F$7)))*(DB!$G$2:$G$2576=AD18)*1))} -> 2
B19: =IFERROR(IF(T19="","",ROW()-13),"") -> 6 | D19: {=IFERROR(INDEX(DB!G$2:G$2576,T19),"")} -> 굴착기 | F19: {=IFERROR(INDEX(DB!O$2:O$2576,T19),"")} -> 깔림 뒤집힘 | H19: {=IFERROR(INDEX(DB!P$2:P$2576,T19),"")} -> 2020년 9월경 OOO시 OO구 OO동 소재 OOOO(주)가 시공 중인 「OOOO 일원 노후관 교체공사」현장에서 재해자가 굴삭기를 운전하여 화물자동차에서 내리던 중 넘어지는 굴삭기에 깔려 병원으로 이송치료 중 사망한 재해임. | J19: {=IFERROR(INDEX(DB!Q$2:Q$2576,T19),"")} -> 굴삭기를 현장으로 반입하기 위해 화물차에서 굴삭기를 내리는 중 전도되는 굴삭기에 깔림 | L19: {=IFERROR(INDEX(DB!R$2:R$2576,T19),"")} -> ▶ 화물자동차에서 발판 등을 사용하여 굴삭기를 내리는 경우 충분한 길이, 폭, 강도를 가진것을 사용 ▶ 굴삭기 스스로 화물차에서 하역하는 경우 지반이 평탄한 곳에서 작업하며, 작업계획서에 따른 작업실시 | P19: {=IFERROR(_xlfn.AGGREGATE(15,6,ROW(DB!A$2:A$2576)/((($D$3<>"YES")+($D$3="YES")*(DB!E$2:E$2576="YES"))*(($D$4="")+($D$4<>"")*( DB!B$2:B$2576=$D$4))*(($D$5="")+($D$5<>"")*( DB!C$2:C$2576=$D$5))*(($D$6="")+($D$6<>"")*( DB!D$2:D$2576=$D$6))*(($D$7="")+($D$7<>"")*(ISNUMBER(SEARCH($D$7,DB!G$2:G$2576))))*(($F$7="전체")+($F$7<>"전체")*(DB!H$2:H$2576=$F$7))),ROW()-13)-1,"")} -> 363 | Q19: {=IFERROR(INDEX(DB!G$2:G$2576,P19),"")} -> 이동식크레인 | R19: {=IFERROR(INDEX(DB!O$2:O$2576,P19),"")} -> 떨어짐 | S19: =IF(P19="","",COUNTIF($Q$14:$Q$2587,"<"&Q19)*100+COUNTIF($R$14:$R$2587,"<"&R19)+(ROW()-13)*0.001) -> 252251.01 | T19: =IFERROR(INDEX($P$14:$P$2587,MATCH(SMALL($S$14:$S$2587,ROW()-13),$S$14:$S$2587,0)),"") -> 383 | U19: {=IFERROR(INDEX(AA$14:AA$63,_xlfn.AGGREGATE(15,6,ROW(AA$14:AA$63)-ROW(AA$14)+1/(AB$14:AB$63=LARGE(AB$14:AB$63,ROW()-13)),COUNTIF(V$14:V18,LARGE(AB$14:AB$63,ROW()-13))+1)),"")} | V19: =IF(U19="","",IFERROR(LARGE(AB$14:AB$63,ROW()-13),"")) | X19: {=IFERROR(INDEX(AD$14:AD$63,_xlfn.AGGREGATE(15,6,ROW(AD$14:AD$63)-ROW(AD$14)+1/(AE$14:AE$63=LARGE(AE$14:AE$63,ROW()-13)),COUNTIF(Y$14:Y18,LARGE(AE$14:AE$63,ROW()-13))+1)),"")} -> 배관 | Y19: =IF(X19="","",IFERROR(LARGE(AE$14:AE$63,ROW()-13),"")) -> 6 | AA19: {=IFERROR(INDEX(DB!$C$2:$C$2576,_xlfn.AGGREGATE(15,6,ROW(DB!$C$2:$C$2576)-1/((($D$3<>"YES")+($D$3="YES")*(DB!$E$2:$E$2576="YES"))*(($D$4="")+($D$4<>"")*(DB!$B$2:$B$2576=$D$4))*(($F$7="전체")+($F$7<>"전체")*(DB!$H$2:$H$2576=$F$7))*(COUNTIF(AA$13:AA18,DB!$C$2:$C$2576)=0)),1)),"")} | AB19: {=IF(AA19="","",SUMPRODUCT(((($D$3<>"YES")+($D$3="YES")*(DB!$E$2:$E$2576="YES"))*(($D$4="")+($D$4<>"")*(DB!$B$2:$B$2576=$D$4))*(($F$7="전체")+($F$7<>"전체")*(DB!$H$2:$H$2576=$F$7)))*(DB!$C$2:$C$2576=AA19)*1))} | AD19: {=IFERROR(INDEX(DB!$G$2:$G$2576,_xlfn.AGGREGATE(15,6,ROW(DB!$G$2:$G$2576)-1/((($D$3<>"YES")+($D$3="YES")*(DB!$E$2:$E$2576="YES"))*(($D$4="")+($D$4<>"")*(DB!$B$2:$B$2576=$D$4))*(($D$5="")+($D$5<>"")*(DB!$C$2:$C$2576=$D$5))*(($D$6="")+($D$6<>"")*(DB!$D$2:$D$2576=$D$6))*(($D$7="")+($D$7<>"")*(ISNUMBER(SEARCH($D$7,DB!$G$2:$G$2576))))*(($F$7="전체")+($F$7<>"전체")*(DB!$H$2:$H$2576=$F$7))*(COUNTIF(AD$13:AD18,DB!$G$2:$G$2576)=0)),1)),"")} -> 트럭 | AE19: {=IF(AD19="","",SUMPRODUCT(((($D$3<>"YES")+($D$3="YES")*(DB!$E$2:$E$2576="YES"))*(($D$4="")+($D$4<>"")*(DB!$B$2:$B$2576=$D$4))*(($D$5="")+($D$5<>"")*(DB!$C$2:$C$2576=$D$5))*(($D$6="")+($D$6<>"")*(DB!$D$2:$D$2576=$D$6))*(($D$7="")+($D$7<>"")*(ISNUMBER(SEARCH($D$7,DB!$G$2:$G$2576))))*(($F$7="전체")+($F$7<>"전체")*(DB!$H$2:$H$2576=$F$7)))*(DB!$G$2:$G$2576=AD19)*1))} -> 11
B20: =IFERROR(IF(T20="","",ROW()-13),"") -> 7 | D20: {=IFERROR(INDEX(DB!G$2:G$2576,T20),"")} -> 굴착기 | F20: {=IFERROR(INDEX(DB!O$2:O$2576,T20),"")} -> 깔림 뒤집힘 | H20: {=IFERROR(INDEX(DB!P$2:P$2576,T20),"")} -> 2019년 12월경 OO시 소재 OOOO 배수로 정비공사 현장에서 PC(Precast Concrete)사각맨홀(약1.83ton, 가로1m×세로1m×높이1.7m)을 설치하기 위해 굴삭기를 사용하여 맨홀을 인양·운반하고, 매설 지점에서 내리는 순간굴삭기가 전도되어 우측면에 있던 재해자 OOO이 굴삭기에 깔려 사망한 재해임 | J20: {=IFERROR(INDEX(DB!Q$2:Q$2576,T20),"")} -> 굴삭기를 사용하여 맨홀 인양 및 운반 중 균형을 잃고 전도되어 근로자 깔림 | L20: {=IFERROR(INDEX(DB!R$2:R$2576,T20),"")} -> ▶ 중량물 인양 시 굴삭기의 정격하중을 준수하여 무리한 중량물 인양 금지 ▶ 차량계 건설기계 사용시 작업 장소 내에 근로자의 출입 통제 ▶ 유도자를 배치하여 차량계 건설기계 유도 | P20: {=IFERROR(_xlfn.AGGREGATE(15,6,ROW(DB!A$2:A$2576)/((($D$3<>"YES")+($D$3="YES")*(DB!E$2:E$2576="YES"))*(($D$4="")+($D$4<>"")*( DB!B$2:B$2576=$D$4))*(($D$5="")+($D$5<>"")*( DB!C$2:C$2576=$D$5))*(($D$6="")+($D$6<>"")*( DB!D$2:D$2576=$D$6))*(($D$7="")+($D$7<>"")*(ISNUMBER(SEARCH($D$7,DB!G$2:G$2576))))*(($F$7="전체")+($F$7<>"전체")*(DB!H$2:H$2576=$F$7))),ROW()-13)-1,"")} -> 364 | Q20: {=IFERROR(INDEX(DB!G$2:G$2576,P20),"")} -> 굴착기 | R20: {=IFERROR(INDEX(DB!O$2:O$2576,P20),"")} -> 맞음 | S20: =IF(P20="","",COUNTIF($Q$14:$Q$2587,"<"&Q20)*100+COUNTIF($R$14:$R$2587,"<"&R20)+(ROW()-13)*0.001) -> 244675.01 | T20: =IFERROR(INDEX($P$14:$P$2587,MATCH(SMALL($S$14:$S$2587,ROW()-13),$S$14:$S$2587,0)),"") -> 398 | U20: {=IFERROR(INDEX(AA$14:AA$63,_xlfn.AGGREGATE(15,6,ROW(AA$14:AA$63)-ROW(AA$14)+1/(AB$14:AB$63=LARGE(AB$14:AB$63,ROW()-13)),COUNTIF(V$14:V19,LARGE(AB$14:AB$63,ROW()-13))+1)),"")} | V20: =IF(U20="","",IFERROR(LARGE(AB$14:AB$63,ROW()-13),"")) | X20: {=IFERROR(INDEX(AD$14:AD$63,_xlfn.AGGREGATE(15,6,ROW(AD$14:AD$63)-ROW(AD$14)+1/(AE$14:AE$63=LARGE(AE$14:AE$63,ROW()-13)),COUNTIF(Y$14:Y19,LARGE(AE$14:AE$63,ROW()-13))+1)),"")} -> 화학물질 | Y20: =IF(X20="","",IFERROR(LARGE(AE$14:AE$63,ROW()-13),"")) -> 6 | AA20: {=IFERROR(INDEX(DB!$C$2:$C$2576,_xlfn.AGGREGATE(15,6,ROW(DB!$C$2:$C$2576)-1/((($D$3<>"YES")+($D$3="YES")*(DB!$E$2:$E$2576="YES"))*(($D$4="")+($D$4<>"")*(DB!$B$2:$B$2576=$D$4))*(($F$7="전체")+($F$7<>"전체")*(DB!$H$2:$H$2576=$F$7))*(COUNTIF(AA$13:AA19,DB!$C$2:$C$2576)=0)),1)),"")} | AB20: {=IF(AA20="","",SUMPRODUCT(((($D$3<>"YES")+($D$3="YES")*(DB!$E$2:$E$2576="YES"))*(($D$4="")+($D$4<>"")*(DB!$B$2:$B$2576=$D$4))*(($F$7="전체")+($F$7<>"전체")*(DB!$H$2:$H$2576=$F$7)))*(DB!$C$2:$C$2576=AA20)*1))} | AD20: {=IFERROR(INDEX(DB!$G$2:$G$2576,_xlfn.AGGREGATE(15,6,ROW(DB!$G$2:$G$2576)-1/((($D$3<>"YES")+($D$3="YES")*(DB!$E$2:$E$2576="YES"))*(($D$4="")+($D$4<>"")*(DB!$B$2:$B$2576=$D$4))*(($D$5="")+($D$5<>"")*(DB!$C$2:$C$2576=$D$5))*(($D$6="")+($D$6<>"")*(DB!$D$2:$D$2576=$D$6))*(($D$7="")+($D$7<>"")*(ISNUMBER(SEARCH($D$7,DB!$G$2:$G$2576))))*(($F$7="전체")+($F$7<>"전체")*(DB!$H$2:$H$2576=$F$7))*(COUNTIF(AD$13:AD19,DB!$G$2:$G$2576)=0)),1)),"")} -> 기타건설장비 | AE20: {=IF(AD20="","",SUMPRODUCT(((($D$3<>"YES")+($D$3="YES")*(DB!$E$2:$E$2576="YES"))*(($D$4="")+($D$4<>"")*(DB!$B$2:$B$2576=$D$4))*(($D$5="")+($D$5<>"")*(DB!$C$2:$C$2576=$D$5))*(($D$6="")+($D$6<>"")*(DB!$D$2:$D$2576=$D$6))*(($D$7="")+($D$7<>"")*(ISNUMBER(SEARCH($D$7,DB!$G$2:$G$2576))))*(($F$7="전체")+($F$7<>"전체")*(DB!$H$2:$H$2576=$F$7)))*(DB!$G$2:$G$2576=AD20)*1))} -> 1
B21: =IFERROR(IF(T21="","",ROW()-13),"") -> 8 | D21: {=IFERROR(INDEX(DB!G$2:G$2576,T21),"")} -> 굴착기 | F21: {=IFERROR(INDEX(DB!O$2:O$2576,T21),"")} -> 깔림 뒤집힘 | H21: {=IFERROR(INDEX(DB!P$2:P$2576,T21),"")} -> 2020년 1월경 OO시 OO구 OO동 소재 관로정비공사 현장에서 재해자1 OOO이 굴착기를 운전하여 계단(경사 약30°)을 내려오던 중 장비가 중심을 잃어 넘어지며 재해자1이 깔리고, 재해자2 OOO가 재해자1을 구하려 장비에 다가가던 중 장비가 2차로 넘어지며 재해자2도 장비에 깔리며 부상당한 재해임. | J21: {=IFERROR(INDEX(DB!Q$2:Q$2576,T21),"")} -> 굴착기가 계단(경사로) 이동중 전도되어 굴삭기운전원(또는 근로자) 깔림 | L21: {=IFERROR(INDEX(DB!R$2:R$2576,T21),"")} -> ▶ 중량물 인양 시 굴삭기의 정격하중을 준수하여 무리한 중량물 인양 금지 ▶ 차량계 건설기계 사용시 작업 장소 내에 근로자의 출입 통제 ▶ 유도자를 배치하여 차량계 건설기계 유도 | P21: {=IFERROR(_xlfn.AGGREGATE(15,6,ROW(DB!A$2:A$2576)/((($D$3<>"YES")+($D$3="YES")*(DB!E$2:E$2576="YES"))*(($D$4="")+($D$4<>"")*( DB!B$2:B$2576=$D$4))*(($D$5="")+($D$5<>"")*( DB!C$2:C$2576=$D$5))*(($D$6="")+($D$6<>"")*( DB!D$2:D$2576=$D$6))*(($D$7="")+($D$7<>"")*(ISNUMBER(SEARCH($D$7,DB!G$2:G$2576))))*(($F$7="전체")+($F$7<>"전체")*(DB!H$2:H$2576=$F$7))),ROW()-13)-1,"")} -> 365 | Q21: {=IFERROR(INDEX(DB!G$2:G$2576,P21),"")} -> 로울러 | R21: {=IFERROR(INDEX(DB!O$2:O$2576,P21),"")} -> 떨어짐 | S21: =IF(P21="","",COUNTIF($Q$14:$Q$2587,"<"&Q21)*100+COUNTIF($R$14:$R$2587,"<"&R21)+(ROW()-13)*0.001) -> 248951.01 | T21: =IFERROR(INDEX($P$14:$P$2587,MATCH(SMALL($S$14:$S$2587,ROW()-13),$S$14:$S$2587,0)),"") -> 399 | U21: {=IFERROR(INDEX(AA$14:AA$63,_xlfn.AGGREGATE(15,6,ROW(AA$14:AA$63)-ROW(AA$14)+1/(AB$14:AB$63=LARGE(AB$14:AB$63,ROW()-13)),COUNTIF(V$14:V20,LARGE(AB$14:AB$63,ROW()-13))+1)),"")} | V21: =IF(U21="","",IFERROR(LARGE(AB$14:AB$63,ROW()-13),"")) | X21: {=IFERROR(INDEX(AD$14:AD$63,_xlfn.AGGREGATE(15,6,ROW(AD$14:AD$63)-ROW(AD$14)+1/(AE$14:AE$63=LARGE(AE$14:AE$63,ROW()-13)),COUNTIF(Y$14:Y20,LARGE(AE$14:AE$63,ROW()-13))+1)),"")} -> 기타자재(내부마감재,시멘트,마대) | Y21: =IF(X21="","",IFERROR(LARGE(AE$14:AE$63,ROW()-13),"")) -> 4 | AA21: {=IFERROR(INDEX(DB!$C$2:$C$2576,_xlfn.AGGREGATE(15,6,ROW(DB!$C$2:$C$2576)-1/((($D$3<>"YES")+($D$3="YES")*(DB!$E$2:$E$2576="YES"))*(($D$4="")+($D$4<>"")*(DB!$B$2:$B$2576=$D$4))*(($F$7="전체")+($F$7<>"전체")*(DB!$H$2:$H$2576=$F$7))*(COUNTIF(AA$13:AA20,DB!$C$2:$C$2576)=0)),1)),"")} | AB21: {=IF(AA21="","",SUMPRODUCT(((($D$3<>"YES")+($D$3="YES")*(DB!$E$2:$E$2576="YES"))*(($D$4="")+($D$4<>"")*(DB!$B$2:$B$2576=$D$4))*(($F$7="전체")+($F$7<>"전체")*(DB!$H$2:$H$2576=$F$7)))*(DB!$C$2:$C$2576=AA21)*1))} | AD21: {=IFERROR(INDEX(DB!$G$2:$G$2576,_xlfn.AGGREGATE(15,6,ROW(DB!$G$2:$G$2576)-1/((($D$3<>"YES")+($D$3="YES")*(DB!$E$2:$E$2576="YES"))*(($D$4="")+($D$4<>"")*(DB!$B$2:$B$2576=$D$4))*(($D$5="")+($D$5<>"")*(DB!$C$2:$C$2576=$D$5))*(($D$6="")+($D$6<>"")*(DB!$D$2:$D$2576=$D$6))*(($D$7="")+($D$7<>"")*(ISNUMBER(SEARCH($D$7,DB!$G$2:$G$2576))))*(($F$7="전체")+($F$7<>"전체")*(DB!$H$2:$H$2576=$F$7))*(COUNTIF(AD$13:AD20,DB!$G$2:$G$2576)=0)),1)),"")} -> 교통수단 | AE21: {=IF(AD21="","",SUMPRODUCT(((($D$3<>"YES")+($D$3="YES")*(DB!$E$2:$E$2576="YES"))*(($D$4="")+($D$4<>"")*(DB!$B$2:$B$2576=$D$4))*(($D$5="")+($D$5<>"")*(DB!$C$2:$C$2576=$D$5))*(($D$6="")+($D$6<>"")*(DB!$D$2:$D$2576=$D$6))*(($D$7="")+($D$7<>"")*(ISNUMBER(SEARCH($D$7,DB!$G$2:$G$2576))))*(($F$7="전체")+($F$7<>"전체")*(DB!$H$2:$H$2576=$F$7)))*(DB!$G$2:$G$2576=AD21)*1))} -> 1
B22: =IFERROR(IF(T22="","",ROW()-13),"") -> 9 | D22: {=IFERROR(INDEX(DB!G$2:G$2576,T22),"")} -> 교통수단 | F22: {=IFERROR(INDEX(DB!O$2:O$2576,T22),"")} -> 부딪힘 접촉 | H22: {=IFERROR(INDEX(DB!P$2:P$2576,T22),"")} -> 2020년 12월분 경, OOO도 OO시 OO구 소재 「㈜OOOO / OOOO 배수시설 설치공사」 현장에서, OO-OO상 103.475km 지점의 배수로 설치(굴착 및 벤치플룸관 매설)를 위해 선로 상에 올라간 굴착기가, 해당 작업지점을 통과하던 화물열차와 충돌하면서 굴착기 운전원 OOO와 작업을 지휘하던 ㈜OOOO 대표이사 OOO가 사망한 재해임 | J22: {=IFERROR(INDEX(DB!Q$2:Q$2576,T22),"")} -> 배수로 설치(굴착 및 벤치플룸관 매설)를 위해 선로 상에 올라간 굴착기가, 해당 작업지점을 통과하던 화물열차와 충돌 | L22: {=IFERROR(INDEX(DB!R$2:R$2576,T22),"")} -> ▶ 철도운행 안전협의 완료 전에 출입 통제구역 내로 임의 출입금지조치 실시 ▶ 작업인원 안전보호구(안전조끼, 안전모, 안전화) 및 휴대용품(열차감시용 무전기, 호루라기, 경보기, 손전등) 지급 및 착용상태 확인 ▶ 철도 내 작업 시, 근로자 안전을 위한 신호수 역할의 열차감시원 배치 | P22: {=IFERROR(_xlfn.AGGREGATE(15,6,ROW(DB!A$2:A$2576)/((($D$3<>"YES")+($D$3="YES")*(DB!E$2:E$2576="YES"))*(($D$4="")+($D$4<>"")*( DB!B$2:B$2576=$D$4))*(($D$5="")+($D$5<>"")*( DB!C$2:C$2576=$D$5))*(($D$6="")+($D$6<>"")*( DB!D$2:D$2576=$D$6))*(($D$7="")+($D$7<>"")*(ISNUMBER(SEARCH($D$7,DB!G$2:G$2576))))*(($F$7="전체")+($F$7<>"전체")*(DB!H$2:H$2576=$F$7))),ROW()-13)-1,"")} -> 366 | Q22: {=IFERROR(INDEX(DB!G$2:G$2576,P22),"")} -> 굴착기 | R22: {=IFERROR(INDEX(DB!O$2:O$2576,P22),"")} -> 부딪힘 접촉 | S22: =IF(P22="","",COUNTIF($Q$14:$Q$2587,"<"&Q22)*100+COUNTIF($R$14:$R$2587,"<"&R22)+(ROW()-13)*0.001) -> 244741.01 | T22: =IFERROR(INDEX($P$14:$P$2587,MATCH(SMALL($S$14:$S$2587,ROW()-13),$S$14:$S$2587,0)),"") -> 404 | U22: {=IFERROR(INDEX(AA$14:AA$63,_xlfn.AGGREGATE(15,6,ROW(AA$14:AA$63)-ROW(AA$14)+1/(AB$14:AB$63=LARGE(AB$14:AB$63,ROW()-13)),COUNTIF(V$14:V21,LARGE(AB$14:AB$63,ROW()-13))+1)),"")} | V22: =IF(U22="","",IFERROR(LARGE(AB$14:AB$63,ROW()-13),"")) | X22: {=IFERROR(INDEX(AD$14:AD$63,_xlfn.AGGREGATE(15,6,ROW(AD$14:AD$63)-ROW(AD$14)+1/(AE$14:AE$63=LARGE(AE$14:AE$63,ROW()-13)),COUNTIF(Y$14:Y21,LARGE(AE$14:AE$63,ROW()-13))+1)),"")} -> 벽체 | Y22: =IF(X22="","",IFERROR(LARGE(AE$14:AE$63,ROW()-13),"")) -> 4 | AA22: {=IFERROR(INDEX(DB!$C$2:$C$2576,_xlfn.AGGREGATE(15,6,ROW(DB!$C$2:$C$2576)-1/((($D$3<>"YES")+($D$3="YES")*(DB!$E$2:$E$2576="YES"))*(($D$4="")+($D$4<>"")*(DB!$B$2:$B$2576=$D$4))*(($F$7="전체")+($F$7<>"전체")*(DB!$H$2:$H$2576=$F$7))*(COUNTIF(AA$13:AA21,DB!$C$2:$C$2576)=0)),1)),"")} | AB22: {=IF(AA22="","",SUMPRODUCT(((($D$3<>"YES")+($D$3="YES")*(DB!$E$2:$E$2576="YES"))*(($D$4="")+($D$4<>"")*(DB!$B$2:$B$2576=$D$4))*(($F$7="전체")+($F$7<>"전체")*(DB!$H$2:$H$2576=$F$7)))*(DB!$C$2:$C$2576=AA22)*1))} | AD22: {=IFERROR(INDEX(DB!$G$2:$G$2576,_xlfn.AGGREGATE(15,6,ROW(DB!$G$2:$G$2576)-1/((($D$3<>"YES")+($D$3="YES")*(DB!$E$2:$E$2576="YES"))*(($D$4="")+($D$4<>"")*(DB!$B$2:$B$2576=$D$4))*(($D$5="")+($D$5<>"")*(DB!$C$2:$C$2576=$D$5))*(($D$6="")+($D$6<>"")*(DB!$D$2:$D$2576=$D$6))*(($D$7="")+($D$7<>"")*(ISNUMBER(SEARCH($D$7,DB!$G$2:$G$2576))))*(($F$7="전체")+($F$7<>"전체")*(DB!$H$2:$H$2576=$F$7))*(COUNTIF(AD$13:AD21,DB!$G$2:$G$2576)=0)),1)),"")} -> 기타자재(내부마감재,시멘트,마대) | AE22: {=IF(AD22="","",SUMPRODUCT(((($D$3<>"YES")+($D$3="YES")*(DB!$E$2:$E$2576="YES"))*(($D$4="")+($D$4<>"")*(DB!$B$2:$B$2576=$D$4))*(($D$5="")+($D$5<>"")*(DB!$C$2:$C$2576=$D$5))*(($D$6="")+($D$6<>"")*(DB!$D$2:$D$2576=$D$6))*(($D$7="")+($D$7<>"")*(ISNUMBER(SEARCH($D$7,DB!$G$2:$G$2576))))*(($F$7="전체")+($F$7<>"전체")*(DB!$H$2:$H$2576=$F$7)))*(DB!$G$2:$G$2576=AD22)*1))} -> 4
B23: =IFERROR(IF(T23="","",ROW()-13),"") -> 10 | D23: {=IFERROR(INDEX(DB!G$2:G$2576,T23),"")} -> 굴착기 | F23: {=IFERROR(INDEX(DB!O$2:O$2576,T23),"")} -> 끼임 | H23: {=IFERROR(INDEX(DB!P$2:P$2576,T23),"")} -> 2021년 9월경 철도 레일중량화 공사현장에서 재해자가 굴착기 후방에서 PC침목 교환 작업 준비 중 선회하는 굴착기 카운트웨이트와 도저블레이드 사이에 두부가 협착되어 사망 | J23: {=IFERROR(INDEX(DB!Q$2:Q$2576,T23),"")} -> 시야확보가 되지 않은 상태로 선회하는 굴착기 카운터웨이트와 도저블레이드 사이에 근로자가 협착 | L23: {=IFERROR(INDEX(DB!R$2:R$2576,T23),"")} -> ▶ 근로자가 건설기계에 근접하여 작업을 수행하는 경우 유도자를 배치하여 안전한 상태에서 작업 진행 ▶ 차량계 건설기계 접촉 가능 장소 및 사각지대 발생가능성이 높은 건설기계 사용 시 근로자 출입금지 및 유도자 배치 ▶ 건설장비 작업 시 근로자와 장비의 동선을 분리 ▶ 카메라 부착 또는 후방에 근로자의 접근을 알리는 후방센서, 경보장치 등 부착 ▶ 차량계 건설기계 작업전 안전 점검 실시 및 후방카메라 등 방호장치 확인 | P23: {=IFERROR(_xlfn.AGGREGATE(15,6,ROW(DB!A$2:A$2576)/((($D$3<>"YES")+($D$3="YES")*(DB!E$2:E$2576="YES"))*(($D$4="")+($D$4<>"")*( DB!B$2:B$2576=$D$4))*(($D$5="")+($D$5<>"")*( DB!C$2:C$2576=$D$5))*(($D$6="")+($D$6<>"")*( DB!D$2:D$2576=$D$6))*(($D$7="")+($D$7<>"")*(ISNUMBER(SEARCH($D$7,DB!G$2:G$2576))))*(($F$7="전체")+($F$7<>"전체")*(DB!H$2:H$2576=$F$7))),ROW()-13)-1,"")} -> 367 | Q23: {=IFERROR(INDEX(DB!G$2:G$2576,P23),"")} -> 굴착기 | R23: {=IFERROR(INDEX(DB!O$2:O$2576,P23),"")} -> 맞음(낙하물체) | S23: =IF(P23="","",COUNTIF($Q$14:$Q$2587,"<"&Q23)*100+COUNTIF($R$14:$R$2587,"<"&R23)+(ROW()-13)*0.001) -> 244686.01 | T23: =IFERROR(INDEX($P$14:$P$2587,MATCH(SMALL($S$14:$S$2587,ROW()-13),$S$14:$S$2587,0)),"") -> 375 | U23: {=IFERROR(INDEX(AA$14:AA$63,_xlfn.AGGREGATE(15,6,ROW(AA$14:AA$63)-ROW(AA$14)+1/(AB$14:AB$63=LARGE(AB$14:AB$63,ROW()-13)),COUNTIF(V$14:V22,LARGE(AB$14:AB$63,ROW()-13))+1)),"")} | V23: =IF(U23="","",IFERROR(LARGE(AB$14:AB$63,ROW()-13),"")) | X23: {=IFERROR(INDEX(AD$14:AD$63,_xlfn.AGGREGATE(15,6,ROW(AD$14:AD$63)-ROW(AD$14)+1/(AE$14:AE$63=LARGE(AE$14:AE$63,ROW()-13)),COUNTIF(Y$14:Y22,LARGE(AE$14:AE$63,ROW()-13))+1)),"")} -> 수목 | Y23: =IF(X23="","",IFERROR(LARGE(AE$14:AE$63,ROW()-13),"")) -> 4 | AA23: {=IFERROR(INDEX(DB!$C$2:$C$2576,_xlfn.AGGREGATE(15,6,ROW(DB!$C$2:$C$2576)-1/((($D$3<>"YES")+($D$3="YES")*(DB!$E$2:$E$2576="YES"))*(($D$4="")+($D$4<>"")*(DB!$B$2:$B$2576=$D$4))*(($F$7="전체")+($F$7<>"전체")*(DB!$H$2:$H$2576=$F$7))*(COUNTIF(AA$13:AA22,DB!$C$2:$C$2576)=0)),1)),"")} | AB23: {=IF(AA23="","",SUMPRODUCT(((($D$3<>"YES")+($D$3="YES")*(DB!$E$2:$E$2576="YES"))*(($D$4="")+($D$4<>"")*(DB!$B$2:$B$2576=$D$4))*(($F$7="전체")+($F$7<>"전체")*(DB!$H$2:$H$2576=$F$7)))*(DB!$C$2:$C$2576=AA23)*1))} | AD23: {=IFERROR(INDEX(DB!$G$2:$G$2576,_xlfn.AGGREGATE(15,6,ROW(DB!$G$2:$G$2576)-1/((($D$3<>"YES")+($D$3="YES")*(DB!$E$2:$E$2576="YES"))*(($D$4="")+($D$4<>"")*(DB!$B$2:$B$2576=$D$4))*(($D$5="")+($D$5<>"")*(DB!$C$2:$C$2576=$D$5))*(($D$6="")+($D$6<>"")*(DB!$D$2:$D$2576=$D$6))*(($D$7="")+($D$7<>"")*(ISNUMBER(SEARCH($D$7,DB!$G$2:$G$2576))))*(($F$7="전체")+($F$7<>"전체")*(DB!$H$2:$H$2576=$F$7))*(COUNTIF(AD$13:AD22,DB!$G$2:$G$2576)=0)),1)),"")} -> 철근콘크리트자재(철근,콘크리트,PC) | AE23: {=IF(AD23="","",SUMPRODUCT(((($D$3<>"YES")+($D$3="YES")*(DB!$E$2:$E$2576="YES"))*(($D$4="")+($D$4<>"")*(DB!$B$2:$B$2576=$D$4))*(($D$5="")+($D$5<>"")*(DB!$C$2:$C$2576=$D$5))*(($D$6="")+($D$6<>"")*(DB!$D$2:$D$2576=$D$6))*(($D$7="")+($D$7<>"")*(ISNUMBER(SEARCH($D$7,DB!$G$2:$G$2576))))*(($F$7="전체")+($F$7<>"전체")*(DB!$H$2:$H$2576=$F$7)))*(DB!$G$2:$G$2576=AD23)*1))} -> 2
B24: =IFERROR(IF(T24="","",ROW()-13),"") -> 11 | D24: {=IFERROR(INDEX(DB!G$2:G$2576,T24),"")} -> 굴착기 | F24: {=IFERROR(INDEX(DB!O$2:O$2576,T24),"")} -> 끼임 | H24: {=IFERROR(INDEX(DB!P$2:P$2576,T24),"")} -> 2017년 6월경 지중화 전기공사 현장에서 재해자가 굴착기의 버킷에 전신주를 걸어 이동하던 중 경사로 구간에서 전도되는 굴착기에 협착되어 사망 | J24: {=IFERROR(INDEX(DB!Q$2:Q$2576,T24),"")} -> 굴삭기 버켓에 줄걸이 후 운반중 굴삭기 전도에 의해 운전자가 운전석 이탈되어 굴삭기에 협착 | L24: {=IFERROR(INDEX(DB!R$2:R$2576,T24),"")} -> ▶ 굴삭기 사용 중량물 양중시 정격하중 준수 ▶ 작업 시 장비 운전수 안전띠 착용 조치 ▶ 중량물 인양 시 굴삭기의 정격하중을 준수하여 무리한 중량물 인양 금지 ▶ 차량계 건설기계 사용시 작업 장소 내에 근로자의 출입 통제 ▶ 유도자를 배치하여 차량계 건설기계 유도 | P24: {=IFERROR(_xlfn.AGGREGATE(15,6,ROW(DB!A$2:A$2576)/((($D$3<>"YES")+($D$3="YES")*(DB!E$2:E$2576="YES"))*(($D$4="")+($D$4<>"")*( DB!B$2:B$2576=$D$4))*(($D$5="")+($D$5<>"")*( DB!C$2:C$2576=$D$5))*(($D$6="")+($D$6<>"")*( DB!D$2:D$2576=$D$6))*(($D$7="")+($D$7<>"")*(ISNUMBER(SEARCH($D$7,DB!G$2:G$2576))))*(($F$7="전체")+($F$7<>"전체")*(DB!H$2:H$2576=$F$7))),ROW()-13)-1,"")} -> 368 | Q24: {=IFERROR(INDEX(DB!G$2:G$2576,P24),"")} -> 굴착기 | R24: {=IFERROR(INDEX(DB!O$2:O$2576,P24),"")} -> 맞음 | S24: =IF(P24="","",COUNTIF($Q$14:$Q$2587,"<"&Q24)*100+COUNTIF($R$14:$R$2587,"<"&R24)+(ROW()-13)*0.001) -> 244675.01 | T24: =IFERROR(INDEX($P$14:$P$2587,MATCH(SMALL($S$14:$S$2587,ROW()-13),$S$14:$S$2587,0)),"") -> 379 | U24: {=IFERROR(INDEX(AA$14:AA$63,_xlfn.AGGREGATE(15,6,ROW(AA$14:AA$63)-ROW(AA$14)+1/(AB$14:AB$63=LARGE(AB$14:AB$63,ROW()-13)),COUNTIF(V$14:V23,LARGE(AB$14:AB$63,ROW()-13))+1)),"")} | V24: =IF(U24="","",IFERROR(LARGE(AB$14:AB$63,ROW()-13),"")) | X24: {=IFERROR(INDEX(AD$14:AD$63,_xlfn.AGGREGATE(15,6,ROW(AD$14:AD$63)-ROW(AD$14)+1/(AE$14:AE$63=LARGE(AE$14:AE$63,ROW()-13)),COUNTIF(Y$14:Y23,LARGE(AE$14:AE$63,ROW()-13))+1)),"")} -> 슬라브단부 | Y24: =IF(X24="","",IFERROR(LARGE(AE$14:AE$63,ROW()-13),"")) -> 4 | AA24: {=IFERROR(INDEX(DB!$C$2:$C$2576,_xlfn.AGGREGATE(15,6,ROW(DB!$C$2:$C$2576)-1/((($D$3<>"YES")+($D$3="YES")*(DB!$E$2:$E$2576="YES"))*(($D$4="")+($D$4<>"")*(DB!$B$2:$B$2576=$D$4))*(($F$7="전체")+($F$7<>"전체")*(DB!$H$2:$H$2576=$F$7))*(COUNTIF(AA$13:AA23,DB!$C$2:$C$2576)=0)),1)),"")} | AB24: {=IF(AA24="","",SUMPRODUCT(((($D$3<>"YES")+($D$3="YES")*(DB!$E$2:$E$2576="YES"))*(($D$4="")+($D$4<>"")*(DB!$B$2:$B$2576=$D$4))*(($F$7="전체")+($F$7<>"전체")*(DB!$H$2:$H$2576=$F$7)))*(DB!$C$2:$C$2576=AA24)*1))} | AD24: {=IFERROR(INDEX(DB!$G$2:$G$2576,_xlfn.AGGREGATE(15,6,ROW(DB!$G$2:$G$2576)-1/((($D$3<>"YES")+($D$3="YES")*(DB!$E$2:$E$2576="YES"))*(($D$4="")+($D$4<>"")*(DB!$B$2:$B$2576=$D$4))*(($D$5="")+($D$5<>"")*(DB!$C$2:$C$2576=$D$5))*(($D$6="")+($D$6<>"")*(DB!$D$2:$D$2576=$D$6))*(($D$7="")+($D$7<>"")*(ISNUMBER(SEARCH($D$7,DB!$G$2:$G$2576))))*(($F$7="전체")+($F$7<>"전체")*(DB!$H$2:$H$2576=$F$7))*(COUNTIF(AD$13:AD23,DB!$G$2:$G$2576)=0)),1)),"")} -> 기타구조물 | AE24: {=IF(AD24="","",SUMPRODUCT(((($D$3<>"YES")+($D$3="YES")*(DB!$E$2:$E$2576="YES"))*(($D$4="")+($D$4<>"")*(DB!$B$2:$B$2576=$D$4))*(($D$5="")+($D$5<>"")*(DB!$C$2:$C$2576=$D$5))*(($D$6="")+($D$6<>"")*(DB!$D$2:$D$2576=$D$6))*(($D$7="")+($D$7<>"")*(ISNUMBER(SEARCH($D$7,DB!$G$2:$G$2576))))*(($F$7="전체")+($F$7<>"전체")*(DB!$H$2:$H$2576=$F$7)))*(DB!$G$2:$G$2576=AD24)*1))} -> 7
B25: =IFERROR(IF(T25="","",ROW()-13),"") -> 12 | D25: {=IFERROR(INDEX(DB!G$2:G$2576,T25),"")} -> 굴착기 | F25: {=IFERROR(INDEX(DB!O$2:O$2576,T25),"")} -> 끼임 | H25: {=IFERROR(INDEX(DB!P$2:P$2576,T25),"")} -> 2016년 7월경, OOO도 OO군 OO읍 소재, 『OOOO(주) OOO 하수관로 정비사업 시설공사』현장에서 맨홀과 오수관로 연결부에서 인력굴착한 잔여토사를 반출하려던 굴삭기 버켓에 관로배관 연결 준비작업 중이던 재해자가 굴삭기 버켓과 흙막이지보재 사이에 협착하여 사망한 재해임 | J25: {=IFERROR(INDEX(DB!Q$2:Q$2576,T25),"")} -> 관로작업 중 굴삭기 버켓과 흙막이 지보재 사이에 협착 | L25: {=IFERROR(INDEX(DB!R$2:R$2576,T25),"")} -> ▶ 굴착면적에 따를 버킷 교체시 유압이 해제될 경우에도 연결장치(Quick coupler)에서 버킷 이탈방지를 위해 안전핀 체결하여 이중 잠금장치 실시 ▶ 차량계 건설기계를 사용하여 굴착 등 작업을 하는 경우 유도자를 배치하여 안전하게 작업 수행 | P25: {=IFERROR(_xlfn.AGGREGATE(15,6,ROW(DB!A$2:A$2576)/((($D$3<>"YES")+($D$3="YES")*(DB!E$2:E$2576="YES"))*(($D$4="")+($D$4<>"")*( DB!B$2:B$2576=$D$4))*(($D$5="")+($D$5<>"")*( DB!C$2:C$2576=$D$5))*(($D$6="")+($D$6<>"")*( DB!D$2:D$2576=$D$6))*(($D$7="")+($D$7<>"")*(ISNUMBER(SEARCH($D$7,DB!G$2:G$2576))))*(($F$7="전체")+($F$7<>"전체")*(DB!H$2:H$2576=$F$7))),ROW()-13)-1,"")} -> 369 | Q25: {=IFERROR(INDEX(DB!G$2:G$2576,P25),"")} -> 트럭 | R25: {=IFERROR(INDEX(DB!O$2:O$2576,P25),"")} -> 떨어짐 | S25: =IF(P25="","",COUNTIF($Q$14:$Q$2587,"<"&Q25)*100+COUNTIF($R$14:$R$2587,"<"&R25)+(ROW()-13)*0.001) -> 258051.01 | T25: =IFERROR(INDEX($P$14:$P$2587,MATCH(SMALL($S$14:$S$2587,ROW()-13),$S$14:$S$2587,0)),"") -> 387 | U25: {=IFERROR(INDEX(AA$14:AA$63,_xlfn.AGGREGATE(15,6,ROW(AA$14:AA$63)-ROW(AA$14)+1/(AB$14:AB$63=LARGE(AB$14:AB$63,ROW()-13)),COUNTIF(V$14:V24,LARGE(AB$14:AB$63,ROW()-13))+1)),"")} | V25: =IF(U25="","",IFERROR(LARGE(AB$14:AB$63,ROW()-13),"")) | X25: {=IFERROR(INDEX(AD$14:AD$63,_xlfn.AGGREGATE(15,6,ROW(AD$14:AD$63)-ROW(AD$14)+1/(AE$14:AE$63=LARGE(AE$14:AE$63,ROW()-13)),COUNTIF(Y$14:Y24,LARGE(AE$14:AE$63,ROW()-13))+1)),"")} -> 각재(파이프,강관,합판) | Y25: =IF(X25="","",IFERROR(LARGE(AE$14:AE$63,ROW()-13),"")) -> 3 | AA25: {=IFERROR(INDEX(DB!$C$2:$C$2576,_xlfn.AGGREGATE(15,6,ROW(DB!$C$2:$C$2576)-1/((($D$3<>"YES")+($D$3="YES")*(DB!$E$2:$E$2576="YES"))*(($D$4="")+($D$4<>"")*(DB!$B$2:$B$2576=$D$4))*(($F$7="전체")+($F$7<>"전체")*(DB!$H$2:$H$2576=$F$7))*(COUNTIF(AA$13:AA24,DB!$C$2:$C$2576)=0)),1)),"")} | AB25: {=IF(AA25="","",SUMPRODUCT(((($D$3<>"YES")+($D$3="YES")*(DB!$E$2:$E$2576="YES"))*(($D$4="")+($D$4<>"")*(DB!$B$2:$B$2576=$D$4))*(($F$7="전체")+($F$7<>"전체")*(DB!$H$2:$H$2576=$F$7)))*(DB!$C$2:$C$2576=AA25)*1))} | AD25: {=IFERROR(INDEX(DB!$G$2:$G$2576,_xlfn.AGGREGATE(15,6,ROW(DB!$G$2:$G$2576)-1/((($D$3<>"YES")+($D$3="YES")*(DB!$E$2:$E$2576="YES"))*(($D$4="")+($D$4<>"")*(DB!$B$2:$B$2576=$D$4))*(($D$5="")+($D$5<>"")*(DB!$C$2:$C$2576=$D$5))*(($D$6="")+($D$6<>"")*(DB!$D$2:$D$2576=$D$6))*(($D$7="")+($D$7<>"")*(ISNUMBER(SEARCH($D$7,DB!$G$2:$G$2576))))*(($F$7="전체")+($F$7<>"전체")*(DB!$H$2:$H$2576=$F$7))*(COUNTIF(AD$13:AD24,DB!$G$2:$G$2576)=0)),1)),"")} -> 물 | AE25: {=IF(AD25="","",SUMPRODUCT(((($D$3<>"YES")+($D$3="YES")*(DB!$E$2:$E$2576="YES"))*(($D$4="")+($D$4<>"")*(DB!$B$2:$B$2576=$D$4))*(($D$5="")+($D$5<>"")*(DB!$C$2:$C$2576=$D$5))*(($D$6="")+($D$6<>"")*(DB!$D$2:$D$2576=$D$6))*(($D$7="")+($D$7<>"")*(ISNUMBER(SEARCH($D$7,DB!$G$2:$G$2576))))*(($F$7="전체")+($F$7<>"전체")*(DB!$H$2:$H$2576=$F$7)))*(DB!$G$2:$G$2576=AD25)*1))} -> 6
B26: =IFERROR(IF(T26="","",ROW()-13),"") -> 13 | D26: {=IFERROR(INDEX(DB!G$2:G$2576,T26),"")} -> 굴착기 | F26: {=IFERROR(INDEX(DB!O$2:O$2576,T26),"")} -> 맞음 | H26: {=IFERROR(INDEX(DB!P$2:P$2576,T26),"")} -> 2019년 2월경 공영주차장 조성공사에서 재해자가 주차장 배면부 전석쌓기 작업 중 회전하면서 굴착기 돌집게에서 이탈된 전석에 맞아 사망 | J26: {=IFERROR(INDEX(DB!Q$2:Q$2576,T26),"")} -> 굴삭기 붐 끝단에 장착 된 돌집게로 전석을 집어 붐대를 회전하던 중 돌집게에서 낙하하는 전석에 맞음 | L26: {=IFERROR(INDEX(DB!R$2:R$2576,T26),"")} -> ▶ 중량물 제원 및 작업장소를 고려하여 적합한 건설장비 선정 및 사용 ▶ 차량계 하역운반기계 사용할 경우 작업계획서를 작성하고 작업계획에 맞게 작업실시 ▶ 자재인양 등 중량물 취급작업 시 낙하위험 지역에 대해 근로자 출입 통제 | P26: {=IFERROR(_xlfn.AGGREGATE(15,6,ROW(DB!A$2:A$2576)/((($D$3<>"YES")+($D$3="YES")*(DB!E$2:E$2576="YES"))*(($D$4="")+($D$4<>"")*( DB!B$2:B$2576=$D$4))*(($D$5="")+($D$5<>"")*( DB!C$2:C$2576=$D$5))*(($D$6="")+($D$6<>"")*( DB!D$2:D$2576=$D$6))*(($D$7="")+($D$7<>"")*(ISNUMBER(SEARCH($D$7,DB!G$2:G$2576))))*(($F$7="전체")+($F$7<>"전체")*(DB!H$2:H$2576=$F$7))),ROW()-13)-1,"")} -> 370 | Q26: {=IFERROR(INDEX(DB!G$2:G$2576,P26),"")} -> 굴착기 | R26: {=IFERROR(INDEX(DB!O$2:O$2576,P26),"")} -> 부딪힘 접촉 | S26: =IF(P26="","",COUNTIF($Q$14:$Q$2587,"<"&Q26)*100+COUNTIF($R$14:$R$2587,"<"&R26)+(ROW()-13)*0.001) -> 244741.01 | T26: =IFERROR(INDEX($P$14:$P$2587,MATCH(SMALL($S$14:$S$2587,ROW()-13),$S$14:$S$2587,0)),"") -> 364 | U26: {=IFERROR(INDEX(AA$14:AA$63,_xlfn.AGGREGATE(15,6,ROW(AA$14:AA$63)-ROW(AA$14)+1/(AB$14:AB$63=LARGE(AB$14:AB$63,ROW()-13)),COUNTIF(V$14:V25,LARGE(AB$14:AB$63,ROW()-13))+1)),"")} | V26: =IF(U26="","",IFERROR(LARGE(AB$14:AB$63,ROW()-13),"")) | X26: {=IFERROR(INDEX(AD$14:AD$63,_xlfn.AGGREGATE(15,6,ROW(AD$14:AD$63)-ROW(AD$14)+1/(AE$14:AE$63=LARGE(AE$14:AE$63,ROW()-13)),COUNTIF(Y$14:Y25,LARGE(AE$14:AE$63,ROW()-13))+1)),"")} -> 암석 | Y26: =IF(X26="","",IFERROR(LARGE(AE$14:AE$63,ROW()-13),"")) -> 3 | AA26: {=IFERROR(INDEX(DB!$C$2:$C$2576,_xlfn.AGGREGATE(15,6,ROW(DB!$C$2:$C$2576)-1/((($D$3<>"YES")+($D$3="YES")*(DB!$E$2:$E$2576="YES"))*(($D$4="")+($D$4<>"")*(DB!$B$2:$B$2576=$D$4))*(($F$7="전체")+($F$7<>"전체")*(DB!$H$2:$H$2576=$F$7))*(COUNTIF(AA$13:AA25,DB!$C$2:$C$2576)=0)),1)),"")} | AB26: {=IF(AA26="","",SUMPRODUCT(((($D$3<>"YES")+($D$3="YES")*(DB!$E$2:$E$2576="YES"))*(($D$4="")+($D$4<>"")*(DB!$B$2:$B$2576=$D$4))*(($F$7="전체")+($F$7<>"전체")*(DB!$H$2:$H$2576=$F$7)))*(DB!$C$2:$C$2576=AA26)*1))} | AD26: {=IFERROR(INDEX(DB!$G$2:$G$2576,_xlfn.AGGREGATE(15,6,ROW(DB!$G$2:$G$2576)-1/((($D$3<>"YES")+($D$3="YES")*(DB!$E$2:$E$2576="YES"))*(($D$4="")+($D$4<>"")*(DB!$B$2:$B$2576=$D$4))*(($D$5="")+($D$5<>"")*(DB!$C$2:$C$2576=$D$5))*(($D$6="")+($D$6<>"")*(DB!$D$2:$D$2576=$D$6))*(($D$7="")+($D$7<>"")*(ISNUMBER(SEARCH($D$7,DB!$G$2:$G$2576))))*(($F$7="전체")+($F$7<>"전체")*(DB!$H$2:$H$2576=$F$7))*(COUNTIF(AD$13:AD25,DB!$G$2:$G$2576)=0)),1)),"")} -> 바닥(바닥에 걸려 넘어짐) | AE26: {=IF(AD26="","",SUMPRODUCT(((($D$3<>"YES")+($D$3="YES")*(DB!$E$2:$E$2576="YES"))*(($D$4="")+($D$4<>"")*(DB!$B$2:$B$2576=$D$4))*(($D$5="")+($D$5<>"")*(DB!$C$2:$C$2576=$D$5))*(($D$6="")+($D$6<>"")*(DB!$D$2:$D$2576=$D$6))*(($D$7="")+($D$7<>"")*(ISNUMBER(SEARCH($D$7,DB!$G$2:$G$2576))))*(($F$7="전체")+($F$7<>"전체")*(DB!$H$2:$H$2576=$F$7)))*(DB!$G$2:$G$2576=AD26)*1))} -> 1
... B63: =IFERROR(IF(T63="","",ROW()-13),"") -> 50 | D63: {=IFERROR(INDEX(DB!G$2:G$2576,T63),"")} -> 물 | F63: {=IFERROR(INDEX(DB!O$2:O$2576,T63),"")} -> 떨어짐 | H63: {=IFERROR(INDEX(DB!P$2:P$2576,T63),"")} -> 2020년 11월경 OOO시 OO구 소재 OOOO(주)가 시공 중인 「OOOO」현장에서 협력업체 OOOO(주) 소속 재해자가 집수정 설치를 위해 굴착해놓은 피트(우천으로 물이 고인상태)에 빠져있는 것을 동료근로자가 발견 구조하여 병원으로 이송하였으나 당일 사망한 재해임. | J63: {=IFERROR(INDEX(DB!Q$2:Q$2576,T63),"")} -> 집수정 설치를 위해 굴착해놓은 피트(우천으로 물이 고인상태)에 빠져 익사 | L63: {=IFERROR(INDEX(DB!R$2:R$2576,T63),"")} -> ▶ 후속시공이 연속하여 이어지지 않는 경우, 발생한 개구부(집수정 등)는 개구부 덮개 등을 이용하여 막음조치 ▶ 개구부 부근에서 작업 시 안전난간 설치 등 추락방지조치 실시 | P63: {=IFERROR(_xlfn.AGGREGATE(15,6,ROW(DB!A$2:A$2576)/((($D$3<>"YES")+($D$3="YES")*(DB!E$2:E$2576="YES"))*(($D$4="")+($D$4<>"")*( DB!B$2:B$2576=$D$4))*(($D$5="")+($D$5<>"")*( DB!C$2:C$2576=$D$5))*(($D$6="")+($D$6<>"")*( DB!D$2:D$2576=$D$6))*(($D$7="")+($D$7<>"")*(ISNUMBER(SEARCH($D$7,DB!G$2:G$2576))))*(($F$7="전체")+($F$7<>"전체")*(DB!H$2:H$2576=$F$7))),ROW()-13)-1,"")} -> 407 | Q63: {=IFERROR(INDEX(DB!G$2:G$2576,P63),"")} -> 굴착기 | R63: {=IFERROR(INDEX(DB!O$2:O$2576,P63),"")} -> 부딪힘 접촉 | S63: =IF(P63="","",COUNTIF($Q$14:$Q$2587,"<"&Q63)*100+COUNTIF($R$14:$R$2587,"<"&R63)+(ROW()-13)*0.001) -> 244741.05 | T63: =IFERROR(INDEX($P$14:$P$2587,MATCH(SMALL($S$14:$S$2587,ROW()-13),$S$14:$S$2587,0)),"") -> 1537 | U63: {=IFERROR(INDEX(AA$14:AA$63,_xlfn.AGGREGATE(15,6,ROW(AA$14:AA$63)-ROW(AA$14)+1/(AB$14:AB$63=LARGE(AB$14:AB$63,ROW()-13)),COUNTIF(V$14:V62,LARGE(AB$14:AB$63,ROW()-13))+1)),"")} | V63: =IF(U63="","",IFERROR(LARGE(AB$14:AB$63,ROW()-13),"")) | X63: {=IFERROR(INDEX(AD$14:AD$63,_xlfn.AGGREGATE(15,6,ROW(AD$14:AD$63)-ROW(AD$14)+1/(AE$14:AE$63=LARGE(AE$14:AE$63,ROW()-13)),COUNTIF(Y$14:Y62,LARGE(AE$14:AE$63,ROW()-13))+1)),"")} | Y63: =IF(X63="","",IFERROR(LARGE(AE$14:AE$63,ROW()-13),"")) | AA63: {=IFERROR(INDEX(DB!$C$2:$C$2576,_xlfn.AGGREGATE(15,6,ROW(DB!$C$2:$C$2576)-1/((($D$3<>"YES")+($D$3="YES")*(DB!$E$2:$E$2576="YES"))*(($D$4="")+($D$4<>"")*(DB!$B$2:$B$2576=$D$4))*(($F$7="전체")+($F$7<>"전체")*(DB!$H$2:$H$2576=$F$7))*(COUNTIF(AA$13:AA62,DB!$C$2:$C$2576)=0)),1)),"")} | AB63: {=IF(AA63="","",SUMPRODUCT(((($D$3<>"YES")+($D$3="YES")*(DB!$E$2:$E$2576="YES"))*(($D$4="")+($D$4<>"")*(DB!$B$2:$B$2576=$D$4))*(($F$7="전체")+($F$7<>"전체")*(DB!$H$2:$H$2576=$F$7)))*(DB!$C$2:$C$2576=AA63)*1))} | AD63: {=IFERROR(INDEX(DB!$G$2:$G$2576,_xlfn.AGGREGATE(15,6,ROW(DB!$G$2:$G$2576)-1/((($D$3<>"YES")+($D$3="YES")*(DB!$E$2:$E$2576="YES"))*(($D$4="")+($D$4<>"")*(DB!$B$2:$B$2576=$D$4))*(($D$5="")+($D$5<>"")*(DB!$C$2:$C$2576=$D$5))*(($D$6="")+($D$6<>"")*(DB!$D$2:$D$2576=$D$6))*(($D$7="")+($D$7<>"")*(ISNUMBER(SEARCH($D$7,DB!$G$2:$G$2576))))*(($F$7="전체")+($F$7<>"전체")*(DB!$H$2:$H$2576=$F$7))*(COUNTIF(AD$13:AD62,DB!$G$2:$G$2576)=0)),1)),"")} | AE63: {=IF(AD63="","",SUMPRODUCT(((($D$3<>"YES")+($D$3="YES")*(DB!$E$2:$E$2576="YES"))*(($D$4="")+($D$4<>"")*(DB!$B$2:$B$2576=$D$4))*(($D$5="")+($D$5<>"")*(DB!$C$2:$C$2576=$D$5))*(($D$6="")+($D$6<>"")*(DB!$D$2:$D$2576=$D$6))*(($D$7="")+($D$7<>"")*(ISNUMBER(SEARCH($D$7,DB!$G$2:$G$2576))))*(($F$7="전체")+($F$7<>"전체")*(DB!$H$2:$H$2576=$F$7)))*(DB!$G$2:$G$2576=AD63)*1))}
B64: =IFERROR(IF(T64="","",ROW()-13),"") -> 51 | D64: {=IFERROR(INDEX(DB!G$2:G$2576,T64),"")} -> 물 | F64: {=IFERROR(INDEX(DB!O$2:O$2576,T64),"")} -> 떨어짐 | H64: {=IFERROR(INDEX(DB!P$2:P$2576,T64),"")} -> 2021년 9월경, OOO시 OO구 OO동 소재 신축공사 현장에서 OOOO 긴급누수복구공사 연간단가 계약업체인 OOOOO(주) 소속근로자 재해자 OOO이 현장내부 물웅덩이에 빠져 익사한 재해임. | J64: {=IFERROR(INDEX(DB!Q$2:Q$2576,T64),"")} -> 상수도 긴급누수복구공사 현장에서 현장내부 물웅덩이에 빠져 익사 | L64: {=IFERROR(INDEX(DB!R$2:R$2576,T64),"")} -> ▶ 수돗물이 유입되는 것을 막기 위한 시설물 설치 시 수압 등 외력에 의한 파손의 위험에 예방하기 위해 구조검토 실시 ▶ 관리감독자를 두어 기계, 기구 또는 설비의 안전보건점검 및 이상 유무의 확인 실시 | P64: {=IFERROR(_xlfn.AGGREGATE(15,6,ROW(DB!A$2:A$2576)/((($D$3<>"YES")+($D$3="YES")*(DB!E$2:E$2576="YES"))*(($D$4="")+($D$4<>"")*( DB!B$2:B$2576=$D$4))*(($D$5="")+($D$5<>"")*( DB!C$2:C$2576=$D$5))*(($D$6="")+($D$6<>"")*( DB!D$2:D$2576=$D$6))*(($D$7="")+($D$7<>"")*(ISNUMBER(SEARCH($D$7,DB!G$2:G$2576))))*(($F$7="전체")+($F$7<>"전체")*(DB!H$2:H$2576=$F$7))),ROW()-13)-1,"")} -> 408 | Q64: {=IFERROR(INDEX(DB!G$2:G$2576,P64),"")} -> 굴착기 | R64: {=IFERROR(INDEX(DB!O$2:O$2576,P64),"")} -> 부딪힘 접촉 | S64: =IF(P64="","",COUNTIF($Q$14:$Q$2587,"<"&Q64)*100+COUNTIF($R$14:$R$2587,"<"&R64)+(ROW()-13)*0.001) -> 244741.05 | T64: =IFERROR(INDEX($P$14:$P$2587,MATCH(SMALL($S$14:$S$2587,ROW()-13),$S$14:$S$2587,0)),"") -> 1541
B65: =IFERROR(IF(T65="","",ROW()-13),"") -> 52 | D65: {=IFERROR(INDEX(DB!G$2:G$2576,T65),"")} -> 물 | F65: {=IFERROR(INDEX(DB!O$2:O$2576,T65),"")} -> 맞음 | H65: {=IFERROR(INDEX(DB!P$2:P$2576,T65),"")} -> 2016년 11월 경 OOOO(주)이 시공하는 OO도 OO시 OO면 OOOO 일원의 OOOO 조성사업 현장에서 출렁다리 공사 협력업체인 ㈜OOOO 소속 착암공 4명 및 측량공 3명이 파도가 거세지자 출렁다리 주탑 기초부에서 철수하기 위해 갯바위상으로 이동하던 중, 협곡의 저지대를 통과하던 OOOO이 너울성 파도에 휩쓸려 실종되어 해경 및 119에서 수색, 사고발생지점 인근에서 구조하였으나 사망한 재해임 | J65: {=IFERROR(INDEX(DB!Q$2:Q$2576,T65),"")} -> 출렁다리 주탑 기초부 공사에서 악천 후 및 강풍 시 작업을 강행하였으나 작업철수시 너울성 파도로 인한 익사 | L65: {=IFERROR(INDEX(DB!R$2:R$2576,T65),"")} -> ▶ 작업 전 기상상태를 파악하여 악천후 또는 강풍이 예상될 경우 작업중지 ▶ 해상 등에 빠질위험이 있는 경우 구명대 등을 곳곳에 배치하여 익사사고 예방 | P65: {=IFERROR(_xlfn.AGGREGATE(15,6,ROW(DB!A$2:A$2576)/((($D$3<>"YES")+($D$3="YES")*(DB!E$2:E$2576="YES"))*(($D$4="")+($D$4<>"")*( DB!B$2:B$2576=$D$4))*(($D$5="")+($D$5<>"")*( DB!C$2:C$2576=$D$5))*(($D$6="")+($D$6<>"")*( DB!D$2:D$2576=$D$6))*(($D$7="")+($D$7<>"")*(ISNUMBER(SEARCH($D$7,DB!G$2:G$2576))))*(($F$7="전체")+($F$7<>"전체")*(DB!H$2:H$2576=$F$7))),ROW()-13)-1,"")} -> 686 | Q65: {=IFERROR(INDEX(DB!G$2:G$2576,P65),"")} -> 기타자재(내부마감재,시멘트,마대) | R65: {=IFERROR(INDEX(DB!O$2:O$2576,P65),"")} -> 끼임 | S65: =IF(P65="","",COUNTIF($Q$14:$Q$2587,"<"&Q65)*100+COUNTIF($R$14:$R$2587,"<"&R65)+(ROW()-13)*0.001) -> 248544.05 | T65: =IFERROR(INDEX($P$14:$P$2587,MATCH(SMALL($S$14:$S$2587,ROW()-13),$S$14:$S$2587,0)),"") -> 1536
B66: =IFERROR(IF(T66="","",ROW()-13),"") -> 53 | D66: {=IFERROR(INDEX(DB!G$2:G$2576,T66),"")} -> 물 | F66: {=IFERROR(INDEX(DB!O$2:O$2576,T66),"")} -> 익사 | H66: {=IFERROR(INDEX(DB!P$2:P$2576,T66),"")} -> 2020년 9월경 OOO도 OO시 OO구 소재 (주)OO이 시공하는「OOOO 하수도 준설공사(연간단가)」현장에서 협력업체 소속 보통인부가 원형 콘크리트 오수맨홀 내부 바닥(깊이 4.4m, 직경 1m)에서 토사 및 돌 등으로 막혀 있던 유입관로(PE관, D300mm)를 뚫기 위해 준설차 흡입 호스(D125mm)로 준설작업을 하던 중 갑자기 뚫리면서 관로 내부(약 50m 구간)에 고여 있던 오수가 유입되면서 맨홀 내부에 오수가 순식간에 차올라(발목이 찰 정도에서 약 1.8m로 수위 상승) 익사한 재해임 | J66: {=IFERROR(INDEX(DB!Q$2:Q$2576,T66),"")} -> 준설작업 중 관로 내부에 고여 있던 오수가 유입되며 오수가 순식간에 차올라 익사 | L66: {=IFERROR(INDEX(DB!R$2:R$2576,T66),"")} -> ▶ 대피용 기구(사다리, 섬유로프, 구조용 삼각대 등) 비치 내부 작업자와 연락을 할 수 있는 무전기 등 통신장비 지급 ▶ 관로 내부에서 작업을 하는 경우 해당 작업장의 지형ㆍ지반, 기상작용에 의한 위험성 등을 사전에 조사하고 그 결과를 고려하여 근로자에게 주지시킬 것 | P66: {=IFERROR(_xlfn.AGGREGATE(15,6,ROW(DB!A$2:A$2576)/((($D$3<>"YES")+($D$3="YES")*(DB!E$2:E$2576="YES"))*(($D$4="")+($D$4<>"")*( DB!B$2:B$2576=$D$4))*(($D$5="")+($D$5<>"")*( DB!C$2:C$2576=$D$5))*(($D$6="")+($D$6<>"")*( DB!D$2:D$2576=$D$6))*(($D$7="")+($D$7<>"")*(ISNUMBER(SEARCH($D$7,DB!G$2:G$2576))))*(($F$7="전체")+($F$7<>"전체")*(DB!H$2:H$2576=$F$7))),ROW()-13)-1,"")} -> 687 | Q66: {=IFERROR(INDEX(DB!G$2:G$2576,P66),"")} -> 기타자재(내부마감재,시멘트,마대) | R66: {=IFERROR(INDEX(DB!O$2:O$2576,P66),"")} -> 깔림 뒤집힘 | S66: =IF(P66="","",COUNTIF($Q$14:$Q$2587,"<"&Q66)*100+COUNTIF($R$14:$R$2587,"<"&R66)+(ROW()-13)*0.001) -> 248520.05 | T66: =IFERROR(INDEX($P$14:$P$2587,MATCH(SMALL($S$14:$S$2587,ROW()-13),$S$14:$S$2587,0)),"") -> 1539
B67: =IFERROR(IF(T67="","",ROW()-13),"") -> 54 | D67: {=IFERROR(INDEX(DB!G$2:G$2576,T67),"")} -> 물 | F67: {=IFERROR(INDEX(DB!O$2:O$2576,T67),"")} -> 익사 | H67: {=IFERROR(INDEX(DB!P$2:P$2576,T67),"")} -> 2021년 6월경 OOO도 OO시 OO구 소재 (주)OOOO 「OOOO 상수도공사」 현장에서 협력업체 OOOO 소속 재해자와 동료작업자 1명이 #7번 작업구를 통해 기존 노후 상수도관(￠500mm) 내부로 들어가서 세관갱생작업 중 갑작스러운 집중호우로 인해 관로 안으로 물이 차오르자 뒤늦게 나오던 재해자가 빠져나오지 못하고 사망한 재해임._x000D_ | J67: {=IFERROR(INDEX(DB!Q$2:Q$2576,T67),"")} -> 작업구를 통해 기존 노후 상수도관 내부로 들어가서 세관갱생작업 중 갑작스러운 집중호우로 인해 관로 안으로 물이 차오르자 뒤늦게 나오던 재해자가 빠져나오지 못하고 익사 | L67: {=IFERROR(INDEX(DB!R$2:R$2576,T67),"")} -> ▶ 관로 내부에서 작업을 하는 경우 해당 작업장의 지형ㆍ지반, 기상작용에 의한 위험성 등을 사전에 조사하고 그 결과를 고려하여 근로자에게 주지시킬 것 ▶ 사업주는 산업재해가 발생할 급박한 위험이 있을 경우 즉시 작업 중지 후 근로자를 대피시키는 등 필요한 조치 준수 ▶ 대피용 기구(사다리, 섬유로프, 구조용 삼각대 등) 비치 내부 작업자와 연락을 할 수 있는 무전기 등 통신장비 지급 | P67: {=IFERROR(_xlfn.AGGREGATE(15,6,ROW(DB!A$2:A$2576)/((($D$3<>"YES")+($D$3="YES")*(DB!E$2:E$2576="YES"))*(($D$4="")+($D$4<>"")*( DB!B$2:B$2576=$D$4))*(($D$5="")+($D$5<>"")*( DB!C$2:C$2576=$D$5))*(($D$6="")+($D$6<>"")*( DB!D$2:D$2576=$D$6))*(($D$7="")+($D$7<>"")*(ISNUMBER(SEARCH($D$7,DB!G$2:G$2576))))*(($F$7="전체")+($F$7<>"전체")*(DB!H$2:H$2576=$F$7))),ROW()-13)-1,"")} -> 688 | Q67: {=IFERROR(INDEX(DB!G$2:G$2576,P67),"")} -> 철근콘크리트자재(철근,콘크리트,PC) | R67: {=IFERROR(INDEX(DB!O$2:O$2576,P67),"")} -> 깔림 뒤집힘 | S67: =IF(P67="","",COUNTIF($Q$14:$Q$2587,"<"&Q67)*100+COUNTIF($R$14:$R$2587,"<"&R67)+(ROW()-13)*0.001) -> 252820.05 | T67: =IFERROR(INDEX($P$14:$P$2587,MATCH(SMALL($S$14:$S$2587,ROW()-13),$S$14:$S$2587,0)),"") -> 1540
B68: =IFERROR(IF(T68="","",ROW()-13),"") -> 55 | D68: {=IFERROR(INDEX(DB!G$2:G$2576,T68),"")} -> 물 | F68: {=IFERROR(INDEX(DB!O$2:O$2576,T68),"")} -> 폭발 | H68: {=IFERROR(INDEX(DB!P$2:P$2576,T68),"")} -> 2020년 5월경 OOO시 OO구에 소재한 ㈜OOOO이 시공하는 상수도 시설물 정비공사 현장에서 ㈜OOOO 소속 근로자 OOO이 신설된 상수도관(Ø1200㎜, L=5.2m) 내부에서 용접작업을 하던 중 상수도 임시 차단밸브(라인스토퍼)가 파손되며 누수된 수돗물의 압력으로 상수도관 밖으로 밀려나와 물이 차 오른 피트(가로 5.2m * 세로 3.6m * 깊이 2.4m)에서 익사한 재해임. | J68: {=IFERROR(INDEX(DB!Q$2:Q$2576,T68),"")} -> 상수도관 내부에서 용접작업을 하던 중 상수도 임시 차단밸브가 파손되어 누수된 수돗물의 압력으로 상수도 관 밖으로 밀려나와 물이 차오른 피트에서 근로자가 익사 | L68: {=IFERROR(INDEX(DB!R$2:R$2576,T68),"")} -> ▶ 수돗물이 유입되는 것을 막기 위한 시설물 설치 시 수압 등 외력에 의한 파손의 위험에 예방하기 위해 구조검토 실시 ▶ 관리감독자를 두어 기계, 기구 또는 설비의 안전보건점검 및 이상 유무의 확인 실시 | P68: {=IFERROR(_xlfn.AGGREGATE(15,6,ROW(DB!A$2:A$2576)/((($D$3<>"YES")+($D$3="YES")*(DB!E$2:E$2576="YES"))*(($D$4="")+($D$4<>"")*( DB!B$2:B$2576=$D$4))*(($D$5="")+($D$5<>"")*( DB!C$2:C$2576=$D$5))*(($D$6="")+($D$6<>"")*( DB!D$2:D$2576=$D$6))*(($D$7="")+($D$7<>"")*(ISNUMBER(SEARCH($D$7,DB!G$2:G$2576))))*(($F$7="전체")+($F$7<>"전체")*(DB!H$2:H$2576=$F$7))),ROW()-13)-1,"")} -> 689 | Q68: {=IFERROR(INDEX(DB!G$2:G$2576,P68),"")} -> 철근콘크리트자재(철근,콘크리트,PC) | R68: {=IFERROR(INDEX(DB!O$2:O$2576,P68),"")} -> 깔림 뒤집힘 | S68: =IF(P68="","",COUNTIF($Q$14:$Q$2587,"<"&Q68)*100+COUNTIF($R$14:$R$2587,"<"&R68)+(ROW()-13)*0.001) -> 252820.05 | T68: =IFERROR(INDEX($P$14:$P$2587,MATCH(SMALL($S$14:$S$2587,ROW()-13),$S$14:$S$2587,0)),"") -> 1538
B69: =IFERROR(IF(T69="","",ROW()-13),"") -> 56 | D69: {=IFERROR(INDEX(DB!G$2:G$2576,T69),"")} -> 바닥(바닥에 걸려 넘어짐) | F69: {=IFERROR(INDEX(DB!O$2:O$2576,T69),"")} -> 떨어짐 | H69: {=IFERROR(INDEX(DB!P$2:P$2576,T69),"")} -> 2020년 5월경, OOO도 OO군 OO면 소재 OOOO(주) OOOO 보강개발사업 현장에서 재해자가 저수지 농업용수 토출조 구조물내의 플랩밸브에 연결된 송수관 용접 및 설치작업을 하다가 인근 작업차량에서 물을 마시고 토출조 내부로 돌아오던 중 제방 법면 사석위에서 미끄러져 토출조 내부로 미끄러져 추락 사망한 재해임. | J69: {=IFERROR(INDEX(DB!Q$2:Q$2576,T69),"")} -> 근로자가 이동 중 제방 법면 사석위에서 저수지 토출조 내부로 미끄러져 추락 | L69: {=IFERROR(INDEX(DB!R$2:R$2576,T69),"")} -> ▶ 작업자가 법면 상부 등으로 불필요한 이동을 금하고 작업자 이동통로 설치 ▶ 근로자가 추락하거나 넘어질 위험이 있는 상부에서 작업 시 안전난간을 설치하고 추락방지조치 실시하고 부득이한 경우 접근방책 등을 설치 ▶ 근로자가 추락하거나 넘어질 위험이 있는 상부에서 작업 시 개인보호구(안전모, 안전대 등) 지급 및 착용 | P69: {=IFERROR(_xlfn.AGGREGATE(15,6,ROW(DB!A$2:A$2576)/((($D$3<>"YES")+($D$3="YES")*(DB!E$2:E$2576="YES"))*(($D$4="")+($D$4<>"")*( DB!B$2:B$2576=$D$4))*(($D$5="")+($D$5<>"")*( DB!C$2:C$2576=$D$5))*(($D$6="")+($D$6<>"")*( DB!D$2:D$2576=$D$6))*(($D$7="")+($D$7<>"")*(ISNUMBER(SEARCH($D$7,DB!G$2:G$2576))))*(($F$7="전체")+($F$7<>"전체")*(DB!H$2:H$2576=$F$7))),ROW()-13)-1,"")} -> 690 | Q69: {=IFERROR(INDEX(DB!G$2:G$2576,P69),"")} -> 기타자재(내부마감재,시멘트,마대) | R69: {=IFERROR(INDEX(DB!O$2:O$2576,P69),"")} -> 맞음 | S69: =IF(P69="","",COUNTIF($Q$14:$Q$2587,"<"&Q69)*100+COUNTIF($R$14:$R$2587,"<"&R69)+(ROW()-13)*0.001) -> 248575.06 | T69: =IFERROR(INDEX($P$14:$P$2587,MATCH(SMALL($S$14:$S$2587,ROW()-13),$S$14:$S$2587,0)),"") -> 1548
B70: =IFERROR(IF(T70="","",ROW()-13),"") -> 57 | D70: {=IFERROR(INDEX(DB!G$2:G$2576,T70),"")} -> 배관 | F70: {=IFERROR(INDEX(DB!O$2:O$2576,T70),"")} -> 깔림 뒤집힘 | H70: {=IFERROR(INDEX(DB!P$2:P$2576,T70),"")} -> 2018년 5월경 OOO도 OO시 OOO읍 소재 OOOO 현장에서 OOOO 소속 재해자가 동료작업자 1명과 함께 기존에 설치했던 관로를 수정하기 위해 터파기 하부에서 흄관(D=800mm)을 새로 부설하던 중, 경사면 상부에 적치해 놓았던 흄관이 미끄러지면서 재해자가 깔려 사망한 재해임. | J70: {=IFERROR(INDEX(DB!Q$2:Q$2576,T70),"")} -> 크레인으로 인양된 강관파이프를 차량에 적재하던 중, 3단으로 불안정하게 적재된 강관파이프가 붕괴되어 강관파이프에 깔림 | L70: {=IFERROR(INDEX(DB!R$2:R$2576,T70),"")} -> ▶ 자재를 야적하는 경우 평탄한 곳에 적재하며 구름방지조치 실시 ▶ 경사면에서 흄관을 고정하기 위해 쐐기 등을 이용 ▶ 강관파이프를 3단이상 등 과도하게 적재 금지 | P70: {=IFERROR(_xlfn.AGGREGATE(15,6,ROW(DB!A$2:A$2576)/((($D$3<>"YES")+($D$3="YES")*(DB!E$2:E$2576="YES"))*(($D$4="")+($D$4<>"")*( DB!B$2:B$2576=$D$4))*(($D$5="")+($D$5<>"")*( DB!C$2:C$2576=$D$5))*(($D$6="")+($D$6<>"")*( DB!D$2:D$2576=$D$6))*(($D$7="")+($D$7<>"")*(ISNUMBER(SEARCH($D$7,DB!G$2:G$2576))))*(($F$7="전체")+($F$7<>"전체")*(DB!H$2:H$2576=$F$7))),ROW()-13)-1,"")} -> 691 | Q70: {=IFERROR(INDEX(DB!G$2:G$2576,P70),"")} -> 기타자재(내부마감재,시멘트,마대) | R70: {=IFERROR(INDEX(DB!O$2:O$2576,P70),"")} -> 맞음 | S70: =IF(P70="","",COUNTIF($Q$14:$Q$2587,"<"&Q70)*100+COUNTIF($R$14:$R$2587,"<"&R70)+(ROW()-13)*0.001) -> 248575.06 | T70: =IFERROR(INDEX($P$14:$P$2587,MATCH(SMALL($S$14:$S$2587,ROW()-13),$S$14:$S$2587,0)),"") -> 1576
